Workbook

Sheet Kian Eqw Index ETF
A1: <TICKER> | B1: <DTYYYYMMDD> | C1: <FIRST> | D1: <HIGH> | E1: <LOW> | F1: <CLOSE> | G1: <VALUE> | H1: <VOL> | I1: <OPENINT> | J1: <PER> | K1: <OPEN> | L1: <LAST> | M1: Date | N1: Return
A2: Kian Eqw Index ETF | B2: 20220514 | C2: 10000 | D2: 10000 | E2: 10000 | F2: 10000 | G2: 814516880000 | H2: 81451688 | I2: 1412 | J2: D | K2: 10000 | L2: 10000 | M2: =DATE(LEFT(B2,4),MID(B2,5,2),RIGHT(B2,2)) -> 44695
A3: Kian Eqw Index ETF | B3: 20220515 | C3: 10000 | D3: 10000 | E3: 10000 | F3: 10000 | G3: 165978430000 | H3: 16597843 | I3: 875 | J3: D | K3: 10000 | L3: 10000 | M3: =DATE(LEFT(B3,4),MID(B3,5,2),RIGHT(B3,2)) -> 44696 | N3: =F3/F2-1 -> 0
A4: Kian Eqw Index ETF | B4: 20220516 | C4: 10000 | D4: 10000 | E4: 10000 | F4: 10000 | G4: 180060920000 | H4: 18006092 | I4: 1095 | J4: D | K4: 10000 | L4: 10000 | M4: =DATE(LEFT(B4,4),MID(B4,5,2),RIGHT(B4,2)) -> 44697 | N4: =F4/F3-1 -> 0
A5: Kian Eqw Index ETF | B5: 20220517 | C5: 10000 | D5: 10000 | E5: 10000 | F5: 10000 | G5: 141474250000 | H5: 14147425 | I5: 484 | J5: D | K5: 10000 | L5: 10000 | M5: =DATE(LEFT(B5,4),MID(B5,5,2),RIGHT(B5,2)) -> 44698 | N5: =F5/F4-1 -> 0
A6: Kian Eqw Index ETF | B6: 20220518 | C6: 10000 | D6: 10000 | E6: 10000 | F6: 10000 | G6: 19980270000 | H6: 1998027 | I6: 234 | J6: D | K6: 10000 | L6: 10000 | M6: =DATE(LEFT(B6,4),MID(B6,5,2),RIGHT(B6,2)) -> 44699 | N6: =F6/F5-1 -> 0
A7: Kian Eqw Index ETF | B7: 20220521 | C7: 10000 | D7: 10000 | E7: 10000 | F7: 10000 | G7: 32590760000 | H7: 3259076 | I7: 253 | J7: D | K7: 10000 | L7: 10000 | M7: =DATE(LEFT(B7,4),MID(B7,5,2),RIGHT(B7,2)) -> 44702 | N7: =F7/F6-1 -> 0
A8: Kian Eqw Index ETF | B8: 20220522 | C8: 10000 | D8: 10000 | E8: 10000 | F8: 10000 | G8: 17258470000 | H8: 1725847 | I8: 221 | J8: D | K8: 10000 | L8: 10000 | M8: =DATE(LEFT(B8,4),MID(B8,5,2),RIGHT(B8,2)) -> 44703 | N8: =F8/F7-1 -> 0
A9: Kian Eqw Index ETF | B9: 20220523 | C9: 10000 | D9: 10000 | E9: 10000 | F9: 10000 | G9: 9162840000 | H9: 916284 | I9: 145 | J9: D | K9: 10000 | L9: 10000 | M9: =DATE(LEFT(B9,4),MID(B9,5,2),RIGHT(B9,2)) -> 44704 | N9: =F9/F8-1 -> 0
A10: Kian Eqw Index ETF | B10: 20220524 | C10: 10000 | D10: 10000 | E10: 10000 | F10: 10000 | G10: 14975860000 | H10: 1497586 | I10: 225 | J10: D | K10: 10000 | L10: 10000 | M10: =DATE(LEFT(B10,4),MID(B10,5,2),RIGHT(B10,2)) -> 44705 | N10: =F10/F9-1 -> 0
A11: Kian Eqw Index ETF | B11: 20220525 | C11: 10000 | D11: 10000 | E11: 10000 | F11: 10000 | G11: 46578160000 | H11: 4657816 | I11: 667 | J11: D | K11: 10000 | L11: 10000 | M11: =DATE(LEFT(B11,4),MID(B11,5,2),RIGHT(B11,2)) -> 44706 | N11: =F11/F10-1 -> 0
A12: Kian Eqw Index ETF | B12: 20220528 | C12: 0 | D12: 0 | E12: 0 | F12: 10000 | G12: 0 | H12: 0 | I12: 0 | J12: D | K12: 10000 | L12: 10000 | M12: =DATE(LEFT(B12,4),MID(B12,5,2),RIGHT(B12,2)) -> 44709 | N12: =F12/F11-1 -> 0
A13: Kian Eqw Index ETF | B13: 20220529 | C13: 0 | D13: 0 | E13: 0 | F13: 10000 | G13: 0 | H13: 0 | I13: 0 | J13: D | K13: 10000 | L13: 10000 | M13: =DATE(LEFT(B13,4),MID(B13,5,2),RIGHT(B13,2)) -> 44710 | N13: =F13/F12-1 -> 0
A14: Kian Eqw Index ETF | B14: 20220530 | C14: 0 | D14: 0 | E14: 0 | F14: 10000 | G14: 0 | H14: 0 | I14: 0 | J14: D | K14: 10000 | L14: 10000 | M14: =DATE(LEFT(B14,4),MID(B14,5,2),RIGHT(B14,2)) -> 44711 | N14: =F14/F13-1 -> 0
... A1010: Kian Eqw Index ETF | B1010: 20260805 | C1010: 35004 | D1010: 35004 | E1010: 35004 | F1010: 35004 | G1010: 33326818344 | H1010: 952086 | I1010: 74 | J1010: D | K1010: 33985 | L1010: 35004 | M1010: =DATE(LEFT(B1010,4),MID(B1010,5,2),RIGHT(B1010,2)) -> 46239 | N1010: =F1010/F1009-1 -> 0.029983816
N1011: =F1011/F1010-1 -> -1

Sheet Owj Damavand ETF
A1: <TICKER> | B1: <DTYYYYMMDD> | C1: <FIRST> | D1: <HIGH> | E1: <LOW> | F1: <CLOSE> | G1: <VALUE> | H1: <VOL> | I1: <OPENINT> | J1: <PER> | K1: <OPEN> | L1: <LAST> | M1: Date | N1: Return
A2: Owj Damavand ETF | B2: 20211011 | C2: 0 | D2: 0 | E2: 0 | F2: 10000 | G2: 0 | H2: 0 | I2: 0 | J2: D | K2: 10000 | L2: 10000 | M2: =DATE(LEFT(B2,4),MID(B2,5,2),RIGHT(B2,2)) -> 44480
A3: Owj Damavand ETF | B3: 20211012 | C3: 10000 | D3: 10000 | E3: 10000 | F3: 10000 | G3: 270792650000 | H3: 27079265 | I3: 797 | J3: D | K3: 10000 | L3: 10000 | M3: =DATE(LEFT(B3,4),MID(B3,5,2),RIGHT(B3,2)) -> 44481 | N3: =F3/F2-1 -> 0
A4: Owj Damavand ETF | B4: 20211013 | C4: 10000 | D4: 10000 | E4: 10000 | F4: 10000 | G4: 59669330000 | H4: 5966933 | I4: 533 | J4: D | K4: 10000 | L4: 10000 | M4: =DATE(LEFT(B4,4),MID(B4,5,2),RIGHT(B4,2)) -> 44482 | N4: =F4/F3-1 -> 0
A5: Owj Damavand ETF | B5: 20211016 | C5: 0 | D5: 0 | E5: 0 | F5: 10000 | G5: 0 | H5: 0 | I5: 0 | J5: D | K5: 10000 | L5: 10000 | M5: =DATE(LEFT(B5,4),MID(B5,5,2),RIGHT(B5,2)) -> 44485 | N5: =F5/F4-1 -> 0
A6: Owj Damavand ETF | B6: 20211017 | C6: 0 | D6: 0 | E6: 0 | F6: 10000 | G6: 0 | H6: 0 | I6: 0 | J6: D | K6: 10000 | L6: 10000 | M6: =DATE(LEFT(B6,4),MID(B6,5,2),RIGHT(B6,2)) -> 44486 | N6: =F6/F5-1 -> 0
A7: Owj Damavand ETF | B7: 20211018 | C7: 0 | D7: 0 | E7: 0 | F7: 10000 | G7: 0 | H7: 0 | I7: 0 | J7: D | K7: 10000 | L7: 10000 | M7: =DATE(LEFT(B7,4),MID(B7,5,2),RIGHT(B7,2)) -> 44487 | N7: =F7/F6-1 -> 0
A8: Owj Damavand ETF | B8: 20211019 | C8: 0 | D8: 0 | E8: 0 | F8: 10000 | G8: 0 | H8: 0 | I8: 0 | J8: D | K8: 10000 | L8: 10000 | M8: =DATE(LEFT(B8,4),MID(B8,5,2),RIGHT(B8,2)) -> 44488 | N8: =F8/F7-1 -> 0
A9: Owj Damavand ETF | B9: 20211020 | C9: 0 | D9: 0 | E9: 0 | F9: 10000 | G9: 0 | H9: 0 | I9: 0 | J9: D | K9: 10000 | L9: 10000 | M9: =DATE(LEFT(B9,4),MID(B9,5,2),RIGHT(B9,2)) -> 44489 | N9: =F9/F8-1 -> 0
A10: Owj Damavand ETF | B10: 20211023 | C10: 0 | D10: 0 | E10: 0 | F10: 10000 | G10: 0 | H10: 0 | I10: 0 | J10: D | K10: 10000 | L10: 10000 | M10: =DATE(LEFT(B10,4),MID(B10,5,2),RIGHT(B10,2)) -> 44492 | N10: =F10/F9-1 -> 0
A11: Owj Damavand ETF | B11: 20211025 | C11: 0 | D11: 0 | E11: 0 | F11: 10000 | G11: 0 | H11: 0 | I11: 0 | J11: D | K11: 10000 | L11: 10000 | M11: =DATE(LEFT(B11,4),MID(B11,5,2),RIGHT(B11,2)) -> 44494 | N11: =F11/F10-1 -> 0
A12: Owj Damavand ETF | B12: 20211026 | C12: 0 | D12: 0 | E12: 0 | F12: 10000 | G12: 0 | H12: 0 | I12: 0 | J12: D | K12: 10000 | L12: 10000 | M12: =DATE(LEFT(B12,4),MID(B12,5,2),RIGHT(B12,2)) -> 44495 | N12: =F12/F11-1 -> 0
A13: Owj Damavand ETF | B13: 20211027 | C13: 0 | D13: 0 | E13: 0 | F13: 10000 | G13: 0 | H13: 0 | I13: 0 | J13: D | K13: 10000 | L13: 10000 | M13: =DATE(LEFT(B13,4),MID(B13,5,2),RIGHT(B13,2)) -> 44496 | N13: =F13/F12-1 -> 0
A14: Owj Damavand ETF | B14: 20211030 | C14: 0 | D14: 0 | E14: 0 | F14: 10000 | G14: 0 | H14: 0 | I14: 0 | J14: D | K14: 10000 | L14: 10000 | M14: =DATE(LEFT(B14,4),MID(B14,5,2),RIGHT(B14,2)) -> 44499 | N14: =F14/F13-1 -> 0
... A1152: Owj Damavand ETF | B1152: 20260805 | C1152: 39048 | D1152: 39048 | E1152: 39000 | F1152: 39047 | G1152: 1549985960 | H1152: 39695 | I1152: 13 | J1152: D | K1152: 37911 | L1152: 39048 | M1152: =DATE(LEFT(B1152,4),MID(B1152,5,2),RIGHT(B1152,2)) -> 46239 | N1152: =F1152/F1151-1 -> 0.029964918
N1153: =F1153/F1152-1 -> -1

Sheet Berelian ETF
A1: <TICKER> | B1: <DTYYYYMMDD> | C1: <FIRST> | D1: <HIGH> | E1: <LOW> | F1: <CLOSE> | G1: <VALUE> | H1: <VOL> | I1: <OPENINT> | J1: <PER> | K1: <OPEN> | L1: <LAST> | M1: Date | N1: Return
A2: Berelian ETF | B2: 20220705 | C2: 0 | D2: 0 | E2: 0 | F2: 10000 | G2: 0 | H2: 0 | I2: 0 | J2: D | K2: 10000 | L2: 10000 | M2: =DATE(LEFT(B2,4),MID(B2,5,2),RIGHT(B2,2)) -> 44747
A3: Berelian ETF | B3: 20220706 | C3: 0 | D3: 0 | E3: 0 | F3: 10000 | G3: 0 | H3: 0 | I3: 0 | J3: D | K3: 10000 | L3: 10000 | M3: =DATE(LEFT(B3,4),MID(B3,5,2),RIGHT(B3,2)) -> 44748 | N3: =F3/F2-1 -> 0
A4: Berelian ETF | B4: 20220709 | C4: 0 | D4: 0 | E4: 0 | F4: 10000 | G4: 0 | H4: 0 | I4: 0 | J4: D | K4: 10000 | L4: 10000 | M4: =DATE(LEFT(B4,4),MID(B4,5,2),RIGHT(B4,2)) -> 44751 | N4: =F4/F3-1 -> 0
A5: Berelian ETF | B5: 20220711 | C5: 10000 | D5: 10000 | E5: 10000 | F5: 10000 | G5: 6066690000 | H5: 606669 | I5: 207 | J5: D | K5: 10000 | L5: 10000 | M5: =DATE(LEFT(B5,4),MID(B5,5,2),RIGHT(B5,2)) -> 44753 | N5: =F5/F4-1 -> 0
A6: Berelian ETF | B6: 20220712 | C6: 10000 | D6: 10000 | E6: 10000 | F6: 10000 | G6: 14411340000 | H6: 1441134 | I6: 367 | J6: D | K6: 10000 | L6: 10000 | M6: =DATE(LEFT(B6,4),MID(B6,5,2),RIGHT(B6,2)) -> 44754 | N6: =F6/F5-1 -> 0
A7: Berelian ETF | B7: 20220713 | C7: 10000 | D7: 10000 | E7: 10000 | F7: 10000 | G7: 15963680000 | H7: 1596368 | I7: 337 | J7: D | K7: 10000 | L7: 10000 | M7: =DATE(LEFT(B7,4),MID(B7,5,2),RIGHT(B7,2)) -> 44755 | N7: =F7/F6-1 -> 0
A8: Berelian ETF | B8: 20220716 | C8: 10000 | D8: 10000 | E8: 10000 | F8: 10000 | G8: 29154270000 | H8: 2915427 | I8: 246 | J8: D | K8: 10000 | L8: 10000 | M8: =DATE(LEFT(B8,4),MID(B8,5,2),RIGHT(B8,2)) -> 44758 | N8: =F8/F7-1 -> 0
A9: Berelian ETF | B9: 20220717 | C9: 10000 | D9: 10000 | E9: 10000 | F9: 10000 | G9: 35200830000 | H9: 3520083 | I9: 1272 | J9: D | K9: 10000 | L9: 10000 | M9: =DATE(LEFT(B9,4),MID(B9,5,2),RIGHT(B9,2)) -> 44759 | N9: =F9/F8-1 -> 0
A10: Berelian ETF | B10: 20220719 | C10: 0 | D10: 0 | E10: 0 | F10: 10000 | G10: 0 | H10: 0 | I10: 0 | J10: D | K10: 10000 | L10: 10000 | M10: =DATE(LEFT(B10,4),MID(B10,5,2),RIGHT(B10,2)) -> 44761 | N10: =F10/F9-1 -> 0
A11: Berelian ETF | B11: 20220720 | C11: 0 | D11: 0 | E11: 0 | F11: 10000 | G11: 0 | H11: 0 | I11: 0 | J11: D | K11: 10000 | L11: 10000 | M11: =DATE(LEFT(B11,4),MID(B11,5,2),RIGHT(B11,2)) -> 44762 | N11: =F11/F10-1 -> 0
A12: Berelian ETF | B12: 20220723 | C12: 0 | D12: 0 | E12: 0 | F12: 10000 | G12: 0 | H12: 0 | I12: 0 | J12: D | K12: 10000 | L12: 10000 | M12: =DATE(LEFT(B12,4),MID(B12,5,2),RIGHT(B12,2)) -> 44765 | N12: =F12/F11-1 -> 0
A13: Berelian ETF | B13: 20220724 | C13: 0 | D13: 0 | E13: 0 | F13: 10000 | G13: 0 | H13: 0 | I13: 0 | J13: D | K13: 10000 | L13: 10000 | M13: =DATE(LEFT(B13,4),MID(B13,5,2),RIGHT(B13,2)) -> 44766 | N13: =F13/F12-1 -> 0
A14: Berelian ETF | B14: 20220725 | C14: 0 | D14: 0 | E14: 0 | F14: 10000 | G14: 0 | H14: 0 | I14: 0 | J14: D | K14: 10000 | L14: 10000 | M14: =DATE(LEFT(B14,4),MID(B14,5,2),RIGHT(B14,2)) -> 44767 | N14: =F14/F13-1 -> 0
... A976: Berelian ETF | B976: 20260805 | C976: 34479 | D976: 34479 | E976: 34479 | F976: 34479 | G976: 4138548849 | H976: 120031 | I976: 4 | J976: D | K976: 33475 | L976: 34479 | M976: =DATE(LEFT(B976,4),MID(B976,5,2),RIGHT(B976,2)) -> 46239 | N976: =F976/F975-1 -> 0.029992532
N977: =F977/F976-1 -> -1

Sheet Overall Index
A1: MILADI | B1: SHAMSI | C1: CLOSE | D1: Date | E1: Return
A2: 20200324 | B2: 13990105 | C2: 508665.9 | D2: =DATE(LEFT(A2,4),MID(A2,5,2),RIGHT(A2,2)) -> 43914
A3: 20200325 | B3: 13990106 | C3: 521267.3 | D3: =DATE(LEFT(A3,4),MID(A3,5,2),RIGHT(A3,2)) -> 43915 | E3: =C3/C2-1 -> 0.024773432
A4: 20200328 | B4: 13990109 | C4: 532525.2 | D4: =DATE(LEFT(A4,4),MID(A4,5,2),RIGHT(A4,2)) -> 43918 | E4: =C4/C3-1 -> 0.021597173
A5: 20200329 | B5: 13990110 | C5: 545649.7 | D5: =DATE(LEFT(A5,4),MID(A5,5,2),RIGHT(A5,2)) -> 43919 | E5: =C5/C4-1 -> 0.024645782
A6: 20200330 | B6: 13990111 | C6: 547657.8 | D6: =DATE(LEFT(A6,4),MID(A6,5,2),RIGHT(A6,2)) -> 43920 | E6: =C6/C5-1 -> 0.0036802
A7: 20200404 | B7: 13990116 | C7: 567531.6 | D7: =DATE(LEFT(A7,4),MID(A7,5,2),RIGHT(A7,2)) -> 43925 | E7: =C7/C6-1 -> 0.036288719
A8: 20200405 | B8: 13990117 | C8: 573903.2 | D8: =DATE(LEFT(A8,4),MID(A8,5,2),RIGHT(A8,2)) -> 43926 | E8: =C8/C7-1 -> 0.011226864
A9: 20200406 | B9: 13990118 | C9: 569673.6 | D9: =DATE(LEFT(A9,4),MID(A9,5,2),RIGHT(A9,2)) -> 43927 | E9: =C9/C8-1 -> -0.007369884
A10: 20200407 | B10: 13990119 | C10: 583344.4 | D10: =DATE(LEFT(A10,4),MID(A10,5,2),RIGHT(A10,2)) -> 43928 | E10: =C10/C9-1 -> 0.023997601
A11: 20200408 | B11: 13990120 | C11: 597070.5 | D11: =DATE(LEFT(A11,4),MID(A11,5,2),RIGHT(A11,2)) -> 43929 | E11: =C11/C10-1 -> 0.023530011
A12: 20200411 | B12: 13990123 | C12: 607854.9 | D12: =DATE(LEFT(A12,4),MID(A12,5,2),RIGHT(A12,2)) -> 43932 | E12: =C12/C11-1 -> 0.018062189
A13: 20200412 | B13: 13990124 | C13: 623260.3 | D13: =DATE(LEFT(A13,4),MID(A13,5,2),RIGHT(A13,2)) -> 43933 | E13: =C13/C12-1 -> 0.025343877
A14: 20200413 | B14: 13990125 | C14: 624527.5 | D14: =DATE(LEFT(A14,4),MID(A14,5,2),RIGHT(A14,2)) -> 43934 | E14: =C14/C13-1 -> 0.0020331794
... A1464: 20260802 | B1464: 14050511 | C1464: 5154057.4 | D1464: =DATE(LEFT(A1464,4),MID(A1464,5,2),RIGHT(A1464,2)) -> 46236 | E1464: =C1464/C1463-1 -> 0.019638949

Sheet Kian assets
A1: تاریخ | B1: پنج سهم با بیشترین وزن | C1: سپرده بانکی | D1: وجه نقد | E1: اوراق مشارکت | F1: سایر دارایی‌ها | G1: سایر سهام | H1: GregDate | I1: EquityWeight | J1: CashWeight
A2: 1405/05/17 | B2: 7.91 | C2: 0 | D2: 2.03 | E2: 0 | F2: 4.35 | G2: 86.71 | H2: 46242 | I2: =B2+G2 -> 94.62 | J2: =D2+C2 -> 2.03
A3: 1405/05/16 | B3: 8.07 | C3: 0 | D3: 1.98 | E3: 0 | F3: 4.71 | G3: 86.06 | H3: 46241 | I3: =B3+G3 -> 94.13 | J3: =D3+C3 -> 1.98
A4: 1405/05/15 | B4: 8.07 | C4: 0 | D4: 1.98 | E4: 0 | F4: 4.71 | G4: 86.06 | H4: 46240 | I4: =B4+G4 -> 94.13 | J4: =D4+C4 -> 1.98
A5: 1405/05/14 | B5: 8.07 | C5: 0 | D5: 1.98 | E5: 0 | F5: 4.7 | G5: 86.06 | H5: 46239 | I5: =B5+G5 -> 94.13 | J5: =D5+C5 -> 1.98
A6: 1405/05/13 | B6: 8.04 | C6: 0 | D6: 0.36 | E6: 0 | F6: 7.66 | G6: 85.93 | H6: 46238 | I6: =B6+G6 -> 93.97 | J6: =D6+C6 -> 0.36
A7: 1405/05/12 | B7: 8.04 | C7: 0 | D7: 0.36 | E7: 0 | F7: 7.66 | G7: 85.93 | H7: 46237 | I7: =B7+G7 -> 93.97 | J7: =D7+C7 -> 0.36
A8: 1405/05/11 | B8: 8.13 | C8: 0 | D8: 1.17 | E8: 0 | F8: 9.14 | G8: 85.82 | H8: 46236 | I8: =B8+G8 -> 93.95 | J8: =D8+C8 -> 1.17
A9: 1405/05/10 | B9: 8.12 | C9: 0 | D9: 0.21 | E9: 0 | F9: 7.24 | G9: 87.52 | H9: 46235 | I9: =B9+G9 -> 95.64 | J9: =D9+C9 -> 0.21
A10: 1405/05/09 | B10: 7.98 | C10: 0 | D10: 2.69 | E10: 0 | F10: 6.42 | G10: 86.94 | H10: 46234 | I10: =B10+G10 -> 94.92 | J10: =D10+C10 -> 2.69
A11: 1405/05/08 | B11: 7.98 | C11: 0 | D11: 2.69 | E11: 0 | F11: 6.41 | G11: 86.93 | H11: 46233 | I11: =B11+G11 -> 94.91 | J11: =D11+C11 -> 2.69
A12: 1405/05/07 | B12: 7.98 | C12: 0 | D12: 2.69 | E12: 0 | F12: 6.41 | G12: 86.93 | H12: 46232 | I12: =B12+G12 -> 94.91 | J12: =D12+C12 -> 2.69
A13: 1405/05/06 | B13: 8.28 | C13: 0 | D13: 2.27 | E13: 0 | F13: 6.04 | G13: 87.44 | H13: 46231 | I13: =B13+G13 -> 95.72 | J13: =D13+C13 -> 2.27
... A1098: 1402/05/17 | B1098: 10 | C1098: 0 | D1098: 1.32 | E1098: 0 | F1098: 4.22 | G1098: 85.3 | H1098: 45146 | I1098: =B1098+G1098 -> 95.3 | J1098: =D1098+C1098 -> 1.32

Sheet Damavand assets
A1: تاریخ | B1: پنج سهم با بیشترین وزن | C1: سپرده بانکی | D1: وجه نقد | E1: اوراق مشارکت | F1: سایر دارایی‌ها | G1: سایر سهام | H1: گواهی سپرده کالایی | I1: واحد صندوق | J1: GregDate | K1: EquityWeight | L1: CashWeight
A2: 1405/05/17 | B2: 30.42 | C2: 0.13 | D2: 0 | E2: 2.47 | F2: 3.83 | G2: 63.14 | H2: 0 | I2: 0 | J2: 46242 | K2: =B2+G2 -> 93.56 | L2: =D2+C2 -> 0.13
A3: 1405/05/16 | B3: 31.14 | C3: 0.33 | D3: 0 | E3: 0.4 | F3: 4.05 | G3: 64.08 | H3: 0 | I3: 0 | J3: 46241 | K3: =B3+G3 -> 95.22 | L3: =D3+C3 -> 0.33
A4: 1405/05/15 | B4: 31.14 | C4: 0.33 | D4: 0 | E4: 0.4 | F4: 4.05 | G4: 64.08 | H4: 0 | I4: 0 | J4: 46240 | K4: =B4+G4 -> 95.22 | L4: =D4+C4 -> 0.33
A5: 1405/05/14 | B5: 31.14 | C5: 0.33 | D5: 0 | E5: 0.4 | F5: 4.05 | G5: 64.08 | H5: 0 | I5: 0 | J5: 46239 | K5: =B5+G5 -> 95.22 | L5: =D5+C5 -> 0.33
A6: 1405/05/13 | B6: 31 | C6: 0 | D6: 0 | E6: 0.41 | F6: 4.22 | G6: 64.37 | H6: 0 | I6: 0 | J6: 46238 | K6: =B6+G6 -> 95.37 | L6: =D6+C6 -> 0
A7: 1405/05/12 | B7: 31 | C7: 0 | D7: 0 | E7: 0.41 | F7: 4.22 | G7: 64.37 | H7: 0 | I7: 0 | J7: 46237 | K7: =B7+G7 -> 95.37 | L7: =D7+C7 -> 0
A8: 1405/05/11 | B8: 30.87 | C8: 0.21 | D8: 0 | E8: 0.42 | F8: 4.31 | G8: 64.2 | H8: 0 | I8: 0 | J8: 46236 | K8: =B8+G8 -> 95.07 | L8: =D8+C8 -> 0.21
A9: 1405/05/10 | B9: 30.41 | C9: 0.3 | D9: 0 | E9: 0.99 | F9: 4.21 | G9: 64.09 | H9: 0 | I9: 0 | J9: 46235 | K9: =B9+G9 -> 94.5 | L9: =D9+C9 -> 0.3
A10: 1405/05/09 | B10: 30.48 | C10: 0.21 | D10: 0 | E10: 1.6 | F10: 4.28 | G10: 63.44 | H10: 0 | I10: 0 | J10: 46234 | K10: =B10+G10 -> 93.92 | L10: =D10+C10 -> 0.21
A11: 1405/05/08 | B11: 30.48 | C11: 0.21 | D11: 0 | E11: 1.6 | F11: 4.27 | G11: 63.44 | H11: 0 | I11: 0 | J11: 46233 | K11: =B11+G11 -> 93.92 | L11: =D11+C11 -> 0.21
A12: 1405/05/07 | B12: 30.48 | C12: 0.21 | D12: 0 | E12: 1.6 | F12: 4.27 | G12: 63.44 | H12: 0 | I12: 0 | J12: 46232 | K12: =B12+G12 -> 93.92 | L12: =D12+C12 -> 0.21
A13: 1405/05/06 | B13: 31.05 | C13: 0.21 | D13: 0 | E13: 1.6 | F13: 4.13 | G13: 63.01 | H13: 0 | I13: 0 | J13: 46231 | K13: =B13+G13 -> 94.06 | L13: =D13+C13 -> 0.21
... A1098: 1402/05/17 | B1098: 20.61 | C1098: 0.41 | D1098: 0 | E1098: 0.05 | F1098: 2.98 | G1098: 75.69 | H1098: 0 | I1098: 0 | J1098: 45146 | K1098: =B1098+G1098 -> 96.3 | L1098: =D1098+C1098 -> 0.41

Sheet Berelian assets
A1: تاریخ | B1: پنج سهم با بیشترین وزن | C1: سپرده بانکی | D1: وجه نقد | E1: اوراق مشارکت | F1: سایر دارایی‌ها | G1: سایر سهام | H1: GregDate | I1: EquityWeight | J1: CashWeight
A2: 1405/05/16 | B2: 33.03 | C2: 0 | D2: 5.17 | E2: 0 | F2: 7.2 | G2: 57.85 | H2: 46241 | I2: =B2+G2 -> 90.88 | J2: =D2+C2 -> 5.17
A3: 1405/05/15 | B3: 33.03 | C3: 0 | D3: 5.17 | E3: 0 | F3: 7.2 | G3: 57.85 | H3: 46240 | I3: =B3+G3 -> 90.88 | J3: =D3+C3 -> 5.17
A4: 1405/05/14 | B4: 33.02 | C4: 0 | D4: 5.17 | E4: 0 | F4: 7.19 | G4: 57.84 | H4: 46239 | I4: =B4+G4 -> 90.86 | J4: =D4+C4 -> 5.17
A5: 1405/05/13 | B5: 32.87 | C5: 0 | D5: 6.1 | E5: 0 | F5: 7.44 | G5: 56.43 | H5: 46238 | I5: =B5+G5 -> 89.3 | J5: =D5+C5 -> 6.1
A6: 1405/05/12 | B6: 32.85 | C6: 0 | D6: 6.1 | E6: 0 | F6: 7.43 | G6: 56.41 | H6: 46237 | I6: =B6+G6 -> 89.26 | J6: =D6+C6 -> 6.1
A7: 1405/05/11 | B7: 32.91 | C7: 0 | D7: 4.58 | E7: 0 | F7: 9.27 | G7: 56.05 | H7: 46236 | I7: =B7+G7 -> 88.96 | J7: =D7+C7 -> 4.58
A8: 1405/05/10 | B8: 32.38 | C8: 0 | D8: 4.55 | E8: 0 | F8: 9.51 | G8: 55.34 | H8: 46235 | I8: =B8+G8 -> 87.72 | J8: =D8+C8 -> 4.55
A9: 1405/05/09 | B9: 33.09 | C9: 0 | D9: 3.99 | E9: 0 | F9: 8.3 | G9: 58.85 | H9: 46234 | I9: =B9+G9 -> 91.94 | J9: =D9+C9 -> 3.99
A10: 1405/05/08 | B10: 33.1 | C10: 0 | D10: 3.99 | E10: 0 | F10: 8.3 | G10: 58.85 | H10: 46233 | I10: =B10+G10 -> 91.95 | J10: =D10+C10 -> 3.99
A11: 1405/05/07 | B11: 33.06 | C11: 0 | D11: 3.99 | E11: 0 | F11: 8.29 | G11: 58.79 | H11: 46232 | I11: =B11+G11 -> 91.85 | J11: =D11+C11 -> 3.99
A12: 1405/05/06 | B12: 33.32 | C12: 0 | D12: 4.01 | E12: 0 | F12: 8.23 | G12: 56.95 | H12: 46231 | I12: =B12+G12 -> 90.27 | J12: =D12+C12 -> 4.01
A13: 1405/05/05 | B13: 33.49 | C13: 0 | D13: 3.96 | E13: 0 | F13: 8.2 | G13: 56.88 | H13: 46230 | I13: =B13+G13 -> 90.37 | J13: =D13+C13 -> 3.96
... A1097: 1402/05/17 | B1097: 39.9 | C1097: 0 | D1097: 5.12 | E1097: 0 | F1097: 4.16 | G1097: 50.82 | H1097: 45146 | I1097: =B1097+G1097 -> 90.72 | J1097: =D1097+C1097 -> 5.12

Sheet CleanData
A1: Date | B1: KianClose | C1: DamavandClose | D1: BerelianClose | E1: TEDPIXClose | F1: KianReturn | G1: DamavandReturn | H1: BerlianReturn | I1: TEDPIXReturn | J1: KianActiveReturn | K1: DamavandActiveReturn | L1: BerelianActiveReturn | M1: KianWealth100 | N1: DamavandWealth100 | O1: BerelianWealth100 | P1: TEDPIXWealth100 | Q1: KianMax | R1: DamavandMax | S1: BerelianMax | T1: TEDPIXMax | U1: KianDD | V1: DamavandDD | W1: BerelianDD | X1: TEDPIXDD
A2: 45143 | B2: 15842 | C2: 16330 | D2: 14900 | E2: 2033048.1 | M2: 100 | N2: 100 | O2: 100 | P2: 100 | Q2: =M2 -> 100 | R2: =N2 -> 100 | S2: =O2 -> 100 | T2: =P2 -> 100 | U2: =M2/Q2-1 -> 0 | V2: =N2/R2-1 -> 0 | W2: =O2/S2-1 -> 0 | X2: =P2/T2-1 -> 0
A3: 45144 | B3: 15672 | C3: 16417 | D3: 15230 | E3: 2040011.7 | F3: =B3/B2-1 -> -0.010730968 | G3: =C3/C2-1 -> 0.0053276179 | H3: =D3/D2-1 -> 0.022147651 | I3: =E3/E2-1 -> 0.0034252018 | J3: =F3-I3 -> -0.01415617 | K3: =G3-I3 -> 0.0019024161 | L3: =H3-I3 -> 0.018722449 | M3: =M2*(1+F3) -> 98.926903 | N3: =N2*(1+G3) -> 100.53276 | O3: =O2*(1+H3) -> 102.21477 | P3: =P2*(1+I3) -> 100.34252 | Q3: =MAX($M$2:M3) -> 100 | R3: =MAX($N$2:N3) -> 100.53276 | S3: =MAX($O$2:O3) -> 102.21477 | T3: =MAX($P$2:P3) -> 100.34252 | U3: =M3/Q3-1 -> -0.010730968 | V3: =N3/R3-1 -> 0 | W3: =O3/S3-1 -> 0 | X3: =P3/T3-1 -> 0
A4: 45145 | B4: 15700 | C4: 16508 | D4: 15010 | E4: 2051072.7 | F4: =B4/B3-1 -> 0.0017866258 | G4: =C4/C3-1 -> 0.0055430347 | H4: =D4/D3-1 -> -0.014445174 | I4: =E4/E3-1 -> 0.0054220277 | J4: =F4-I4 -> -0.0036354019 | K4: =G4-I4 -> 0.00012100693 | L4: =H4-I4 -> -0.019867202 | M4: =M3*(1+F4) -> 99.103649 | N4: =N3*(1+G4) -> 101.09002 | O4: =O3*(1+H4) -> 100.73826 | P4: =P3*(1+I4) -> 100.88658 | Q4: =MAX($M$2:M4) -> 100 | R4: =MAX($N$2:N4) -> 101.09002 | S4: =MAX($O$2:O4) -> 102.21477 | T4: =MAX($P$2:P4) -> 100.88658 | U4: =M4/Q4-1 -> -0.0089635147 | V4: =N4/R4-1 -> 0 | W4: =O4/S4-1 -> -0.014445174 | X4: =P4/T4-1 -> 0
A5: 45146 | B5: 15479 | C5: 16332 | D5: 14430 | E5: 2037869.3 | F5: =B5/B4-1 -> -0.014076433 | G5: =C5/C4-1 -> -0.010661497 | H5: =D5/D4-1 -> -0.038640906 | I5: =E5/E4-1 -> -0.0064373145 | J5: =F5-I5 -> -0.0076391186 | K5: =G5-I5 -> -0.004224183 | L5: =H5-I5 -> -0.032203592 | M5: =M4*(1+F5) -> 97.708623 | N5: =N4*(1+G5) -> 100.01225 | O5: =O4*(1+H5) -> 96.845638 | P5: =P4*(1+I5) -> 100.23714 | Q5: =MAX($M$2:M5) -> 100 | R5: =MAX($N$2:N5) -> 101.09002 | S5: =MAX($O$2:O5) -> 102.21477 | T5: =MAX($P$2:P5) -> 100.88658 | U5: =M5/Q5-1 -> -0.022913774 | V5: =N5/R5-1 -> -0.010661497 | W5: =O5/S5-1 -> -0.052527905 | X5: =P5/T5-1 -> -0.0064373145
A6: 45147 | B6: 15465 | C6: 16443 | D6: 14700 | E6: 2036985.5 | F6: =B6/B5-1 -> -0.00090445119 | G6: =C6/C5-1 -> 0.0067964732 | H6: =D6/D5-1 -> 0.018711019 | I6: =E6/E5-1 -> -0.00043368826 | J6: =F6-I6 -> -0.00047076293 | K6: =G6-I6 -> 0.0072301614 | L6: =H6-I6 -> 0.019144707 | M6: =M5*(1+F6) -> 97.62025 | N6: =N5*(1+G6) -> 100.69198 | O6: =O5*(1+H6) -> 98.657718 | P6: =P5*(1+I6) -> 100.19367 | Q6: =MAX($M$2:M6) -> 100 | R6: =MAX($N$2:N6) -> 101.09002 | S6: =MAX($O$2:O6) -> 102.21477 | T6: =MAX($P$2:P6) -> 100.88658 | U6: =M6/Q6-1 -> -0.0237975 | V6: =N6/R6-1 -> -0.0039374849 | W6: =O6/S6-1 -> -0.034799737 | X6: =P6/T6-1 -> -0.006868211
A7: 45150 | B7: 15095 | C7: 15755 | D7: 14260 | E7: 1989639.8 | F7: =B7/B6-1 -> -0.023924992 | G7: =C7/C6-1 -> -0.041841513 | H7: =D7/D6-1 -> -0.029931973 | I7: =E7/E6-1 -> -0.023243023 | J7: =F7-I7 -> -0.00068196932 | K7: =G7-I7 -> -0.018598491 | L7: =H7-I7 -> -0.0066889502 | M7: =M6*(1+F7) -> 95.284686 | N7: =N6*(1+G7) -> 96.478873 | O7: =O6*(1+H7) -> 95.704698 | P7: =P6*(1+I7) -> 97.864866 | Q7: =MAX($M$2:M7) -> 100 | R7: =MAX($N$2:N7) -> 101.09002 | S7: =MAX($O$2:O7) -> 102.21477 | T7: =MAX($P$2:P7) -> 100.88658 | U7: =M7/Q7-1 -> -0.047153137 | V7: =N7/R7-1 -> -0.045614248 | W7: =O7/S7-1 -> -0.063690085 | X7: =P7/T7-1 -> -0.029951596
A8: 45151 | B8: 15104 | C8: 15741 | D8: 14170 | E8: 1987917.9 | F8: =B8/B7-1 -> 0.00059622392 | G8: =C8/C7-1 -> -0.00088860679 | H8: =D8/D7-1 -> -0.0063113604 | I8: =E8/E7-1 -> -0.00086543303 | J8: =F8-I8 -> 0.0014616569 | K8: =G8-I8 -> -2.3173762e-05 | L8: =H8-I8 -> -0.0054459274 | M8: =M7*(1+F8) -> 95.341497 | N8: =N7*(1+G8) -> 96.393141 | O8: =O7*(1+H8) -> 95.100671 | P8: =P7*(1+I8) -> 97.780171 | Q8: =MAX($M$2:M8) -> 100 | R8: =MAX($N$2:N8) -> 101.09002 | S8: =MAX($O$2:O8) -> 102.21477 | T8: =MAX($P$2:P8) -> 100.88658 | U8: =M8/Q8-1 -> -0.046585027 | V8: =N8/R8-1 -> -0.046462321 | W8: =O8/S8-1 -> -0.069599475 | X8: =P8/T8-1 -> -0.030791108
A9: 45152 | B9: 15150 | C9: 15807 | D9: 14260 | E9: 1997030.3 | F9: =B9/B8-1 -> 0.0030455508 | G9: =C9/C8-1 -> 0.0041928721 | H9: =D9/D8-1 -> 0.0063514467 | I9: =E9/E8-1 -> 0.0045838915 | J9: =F9-I9 -> -0.0015383407 | K9: =G9-I9 -> -0.0003910194 | L9: =H9-I9 -> 0.0017675552 | M9: =M8*(1+F9) -> 95.631865 | N9: =N8*(1+G9) -> 96.797306 | O9: =O8*(1+H9) -> 95.704698 | P9: =P8*(1+I9) -> 98.228384 | Q9: =MAX($M$2:M9) -> 100 | R9: =MAX($N$2:N9) -> 101.09002 | S9: =MAX($O$2:O9) -> 102.21477 | T9: =MAX($P$2:P9) -> 100.88658 | U9: =M9/Q9-1 -> -0.043681353 | V9: =N9/R9-1 -> -0.04246426 | W9: =O9/S9-1 -> -0.063690085 | X9: =P9/T9-1 -> -0.026348359
A10: 45153 | B10: 14875 | C10: 15807 | D10: 13960 | E10: 1978182.8 | F10: =B10/B9-1 -> -0.018151815 | G10: =C10/C9-1 -> 0 | H10: =D10/D9-1 -> -0.021037868 | I10: =E10/E9-1 -> -0.0094377637 | J10: =F10-I10 -> -0.0087140515 | K10: =G10-I10 -> 0.0094377637 | L10: =H10-I10 -> -0.011600104 | M10: =M9*(1+F10) -> 93.895973 | N10: =N9*(1+G10) -> 96.797306 | O10: =O9*(1+H10) -> 93.691275 | P10: =P9*(1+I10) -> 97.301328 | Q10: =MAX($M$2:M10) -> 100 | R10: =MAX($N$2:N10) -> 101.09002 | S10: =MAX($O$2:O10) -> 102.21477 | T10: =MAX($P$2:P10) -> 100.88658 | U10: =M10/Q10-1 -> -0.061040273 | V10: =N10/R10-1 -> -0.04246426 | W10: =O10/S10-1 -> -0.08338805 | X10: =P10/T10-1 -> -0.035537453
A11: 45154 | B11: 14893 | C11: 15689 | D11: 13820 | E11: 1973597.3 | F11: =B11/B10-1 -> 0.001210084 | G11: =C11/C10-1 -> -0.0074650471 | H11: =D11/D10-1 -> -0.010028653 | I11: =E11/E10-1 -> -0.0023180365 | J11: =F11-I11 -> 0.0035281206 | K11: =G11-I11 -> -0.0051470106 | L11: =H11-I11 -> -0.0077106168 | M11: =M10*(1+F11) -> 94.009595 | N11: =N10*(1+G11) -> 96.074709 | O11: =O10*(1+H11) -> 92.751678 | P11: =P10*(1+I11) -> 97.07578 | Q11: =MAX($M$2:M11) -> 100 | R11: =MAX($N$2:N11) -> 101.09002 | S11: =MAX($O$2:O11) -> 102.21477 | T11: =MAX($P$2:P11) -> 100.88658 | U11: =M11/Q11-1 -> -0.059904053 | V11: =N11/R11-1 -> -0.049612309 | W11: =O11/S11-1 -> -0.092580433 | X11: =P11/T11-1 -> -0.037773113
A12: 45157 | B12: 14631 | C12: 15423 | D12: 13500 | E12: 1957515.4 | F12: =B12/B11-1 -> -0.017592157 | G12: =C12/C11-1 -> -0.016954554 | H12: =D12/D11-1 -> -0.023154848 | I12: =E12/E11-1 -> -0.0081485215 | J12: =F12-I12 -> -0.0094436359 | K12: =G12-I12 -> -0.0088060327 | L12: =H12-I12 -> -0.015006327 | M12: =M11*(1+F12) -> 92.355763 | N12: =N11*(1+G12) -> 94.445805 | O12: =O11*(1+H12) -> 90.604027 | P12: =P11*(1+I12) -> 96.284756 | Q12: =MAX($M$2:M12) -> 100 | R12: =MAX($N$2:N12) -> 101.09002 | S12: =MAX($O$2:O12) -> 102.21477 | T12: =MAX($P$2:P12) -> 100.88658 | U12: =M12/Q12-1 -> -0.076442368 | V12: =N12/R12-1 -> -0.065725709 | W12: =O12/S12-1 -> -0.1135916 | X12: =P12/T12-1 -> -0.045613839
A13: 45158 | B13: 14609 | C13: 15461 | D13: 13500 | E13: 1954029.7 | F13: =B13/B12-1 -> -0.0015036566 | G13: =C13/C12-1 -> 0.0024638527 | H13: =D13/D12-1 -> 0 | I13: =E13/E12-1 -> -0.0017806756 | J13: =F13-I13 -> 0.00027701903 | K13: =G13-I13 -> 0.0042445283 | L13: =H13-I13 -> 0.0017806756 | M13: =M12*(1+F13) -> 92.216892 | N13: =N12*(1+G13) -> 94.678506 | O13: =O12*(1+H13) -> 90.604027 | P13: =P12*(1+I13) -> 96.113304 | Q13: =MAX($M$2:M13) -> 100 | R13: =MAX($N$2:N13) -> 101.09002 | S13: =MAX($O$2:O13) -> 102.21477 | T13: =MAX($P$2:P13) -> 100.88658 | U13: =M13/Q13-1 -> -0.077831082 | V13: =N13/R13-1 -> -0.063423795 | W13: =O13/S13-1 -> -0.1135916 | X13: =P13/T13-1 -> -0.047313291
A14: 45159 | B14: 14532 | C14: 15500 | D14: 13500 | E14: 1956441.4 | F14: =B14/B13-1 -> -0.0052707235 | G14: =C14/C13-1 -> 0.0025224759 | H14: =D14/D13-1 -> 0 | I14: =E14/E13-1 -> 0.0012342187 | J14: =F14-I14 -> -0.0065049422 | K14: =G14-I14 -> 0.0012882572 | L14: =H14-I14 -> -0.0012342187 | M14: =M13*(1+F14) -> 91.730842 | N14: =N13*(1+G14) -> 94.91733 | O14: =O13*(1+H14) -> 90.604027 | P14: =P13*(1+I14) -> 96.231929 | Q14: =MAX($M$2:M14) -> 100 | R14: =MAX($N$2:N14) -> 101.09002 | S14: =MAX($O$2:O14) -> 102.21477 | T14: =MAX($P$2:P14) -> 100.88658 | U14: =M14/Q14-1 -> -0.082691579 | V14: =N14/R14-1 -> -0.061061304 | W14: =O14/S14-1 -> -0.1135916 | X14: =P14/T14-1 -> -0.046137467
... A658: 46236 | B658: 33004 | C658: 36811 | D658: 32512 | E658: 5154057.4 | F658: =B658/B657-1 -> 0.021068589 | G658: =C658/C657-1 -> 0.015167811 | H658: =D658/D657-1 -> 0.011228267 | I658: =E658/E657-1 -> 0.019638949 | J658: =F658-I658 -> 0.0014296396 | K658: =G658-I658 -> -0.0044711382 | L658: =H658-I658 -> -0.0084106827 | M658: =M657*(1+F658) -> 208.33228 | N658: =N657*(1+G658) -> 225.41947 | O658: =O657*(1+H658) -> 218.20134 | P658: =P657*(1+I658) -> 253.5138 | Q658: =MAX($M$2:M658) -> 208.33228 | R658: =MAX($N$2:N658) -> 227.99755 | S658: =MAX($O$2:O658) -> 228.28859 | T658: =MAX($P$2:P658) -> 261.25913 | U658: =M658/Q658-1 -> 0 | V658: =N658/R658-1 -> -0.011307477 | W658: =O658/S658-1 -> -0.044186388 | X658: =P658/T658-1 -> -0.029646163

Sheet Performance
C1: معیارهای ارزیابی عملکرد پرتفوی - صندوق شاخصی کیان، اوج دماوند و برلیان
A2: نرخ بازده بدون ریسک سالانه (Rf): | B2: 0.3246
A4: معیار | B4: صندوق شاخصی کیان | C4: صندوق اوج دماوند | D4: صندوق برلیان | E4: شاخص کل (بنچمارک)
A5: تعداد مشاهدات | B5: =COUNT(CleanData!F3:F658) -> 656 | C5: =COUNT(CleanData!G3:G658) -> 656 | D5: =COUNT(CleanData!H3:H658) -> 656 | E5: =COUNT(CleanData!I3:I658) -> 656
A6: میانگین بازده روزانه | B6: =AVERAGE(CleanData!F3:F658) -> 0.0012618753 | C6: =AVERAGE(CleanData!G3:G658) -> 0.0013549236 | D6: =AVERAGE(CleanData!H3:H658) -> 0.0013095542 | E6: =AVERAGE(CleanData!I3:I658) -> 0.0014856798
A7: ریسک روزانه (انحراف معیار) | B7: =_xlfn.STDEV.S(CleanData!F3:F658) -> 0.016913222 | C7: =_xlfn.STDEV.S(CleanData!G3:G658) -> 0.015184998 | D7: =_xlfn.STDEV.S(CleanData!H3:H658) -> 0.015472921 | E7: =_xlfn.STDEV.S(CleanData!I3:I658) -> 0.011562419
A8: بازده تجمعی کل دوره | B8: =CleanData!B658/CleanData!B2-1 -> 1.0833228 | C8: =CleanData!C658/CleanData!C2-1 -> 1.2541947 | D8: =CleanData!D658/CleanData!D2-1 -> 1.1820134 | E8: =CleanData!E658/CleanData!E2-1 -> 1.535138
A9: بازده مرکب سالانه (CAGR) | B9: =(1+B8)^(252/B5)-1 -> 0.32571195 | C9: =(1+C8)^(252/C5)-1 -> 0.36647083 | D9: =(1+D8)^(252/D5)-1 -> 0.34949363 | E9: =(1+E8)^(252/E5)-1 -> 0.4295381
A10: ریسک سالانه‌شده | B10: =B7*SQRT(252) -> 0.26848908 | C10: =C7*SQRT(252) -> 0.24105437 | D10: =D7*SQRT(252) -> 0.24562501 | E10: =E7*SQRT(252) -> 0.18354772
A11: بتا (β) | B11: =_xlfn.COVARIANCE.S(CleanData!F3:F658,CleanData!I3:I658)/_xlfn.VAR.S(CleanData!I3:I658) -> 1.2033418 | C11: =_xlfn.COVARIANCE.S(CleanData!G3:G658,CleanData!I3:I658)/_xlfn.VAR.S(CleanData!I3:I658) -> 1.0147928 | D11: =_xlfn.COVARIANCE.S(CleanData!H3:H658,CleanData!I3:I658)/_xlfn.VAR.S(CleanData!I3:I658) -> 1.0103994 | E11: 1
A12: نسبت شارپ | B12: =(B9-$B$2)/B10 -> 0.0041414972 | C12: =(C9-$B$2)/C10 -> 0.17369872 | D12: =(D9-$B$2)/D10 -> 0.10134809 | E12: =(E9-$B$2)/E10 -> 0.5717211
A13: نسبت ترینر | B13: =(B9-$B$2)/B11 -> 0.00092404899 | C13: =(C9-$B$2)/C11 -> 0.041260477 | D13: =(D9-$B$2)/D11 -> 0.024637411 | E13: =(E9-$B$2)/E11 -> 0.1049381
A14: آلفای جنسن (سالانه) | B14: =B9-($B$2+B11*($E$9-$B$2)) -> -0.12516446 | C14: =C9-($B$2+C11*($E$9-$B$2)) -> -0.064619596 | D14: =D9-($B$2+D11*($E$9-$B$2)) -> -0.081135772 | E14: 0
A15: Tracking Error (سالانه) | B15: =_xlfn.STDEV.S(CleanData!J3:J658)*SQRT(252) -> 0.15714817 | C15: =_xlfn.STDEV.S(CleanData!K3:K658)*SQRT(252) -> 0.15303827 | D15: =_xlfn.STDEV.S(CleanData!L3:L658)*SQRT(252) -> 0.16106264 | E15: 0
A16: Information Ratio | B16: =(AVERAGE(CleanData!J3:J658)*252)/B15 -> -0.35888898 | C16: =(AVERAGE(CleanData!K3:K658)*252)/C15 -> -0.2153094 | D16: =(AVERAGE(CleanData!L3:L658)*252)/D15 -> -0.27556764 | E16: -
A17: نسبت سورتینو | B17: {=(B9-$B$2)/(SQRT(SUMPRODUCT((CleanData!F3:F658<0)*(CleanData!F3:F658)^2)/COUNTIF(CleanData!F3:F658,"<0"))*SQRT(252))} -> 0.0044588688 | C17: {=(C9-$B$2)/(SQRT(SUMPRODUCT((CleanData!G3:G658<0)*(CleanData!G3:G658)^2)/COUNTIF(CleanData!G3:G658,"<0"))*SQRT(252))} -> 0.16829488 | D17: {=(D9-$B$2)/(SQRT(SUMPRODUCT((CleanData!H3:H658<0)*(CleanData!H3:H658)^2)/COUNTIF(CleanData!H3:H658,"<0"))*SQRT(252))} -> 0.10239654 | E17: {=(E9-$B$2)/(SQRT(SUMPRODUCT((CleanData!I3:I658<0)*(CleanData!I3:I658)^2)/COUNTIF(CleanData!I3:I658,"<0"))*SQRT(252))} -> 0.62016492
A18: حداکثر افت سرمایه (MDD) | B18: =MIN(CleanData!U2:U658) -> -0.27329387 | C18: =MIN(CleanData!V2:V658) -> -0.26885497 | D18: =MIN(CleanData!W2:W658) -> -0.22345804 | E18: =MIN(CleanData!X2:X658) -> -0.26336621
A20: ترکیب دارایی صندوق‌ها (میانگین در بازه سه‌ساله)
A21: معیار | B21: صندوق شاخصی کیان | C21: صندوق اوج دماوند | D21: صندوق برلیان
A22: میانگین سهم سهام (٪) | B22: =AVERAGE('Kian assets'!I8:I1098)/100 -> 0.96478258 | C22: =AVERAGE('Damavand assets'!K8:K1098)/100 -> 0.95718772 | D22: =AVERAGE('Berelian assets'!I7:I1097)/100 -> 0.9002539
A23: میانگین سهم نقد و سپرده بانکی (٪) | B23: =AVERAGE('Kian assets'!J8:J1098)/100 -> 0.016489368 | C23: =AVERAGE('Damavand assets'!L8:L1098)/100 -> 0.0060644363 | D23: =AVERAGE('Berelian assets'!J7:J1097)/100 -> 0.051292026
A24: میانگین سهم اوراق مشارکت (٪) | B24: =AVERAGE('Kian assets'!E8:E1098)/100 -> 0 | C24: =AVERAGE('Damavand assets'!E8:E1098)/100 -> 0.013603483 | D24: =AVERAGE('Berelian assets'!E7:E1097)/100 -> 0.0077910174
A25: میانگین سایر دارایی‌ها (٪) | B25: =AVERAGE('Kian assets'!F8:F1098)/100 -> 0.03721659 | C25: =AVERAGE('Damavand assets'!F8:F1098)/100 -> 0.021269753 | D25: =AVERAGE('Berelian assets'!F7:F1097)/100 -> 0.023352612
A26: انحراف معیار سهم سهام (نوسان تخصیص) | B26: =_xlfn.STDEV.S('Kian assets'!I8:I1098)/100 -> 0.025056324 | C26: =_xlfn.STDEV.S('Damavand assets'!K8:K1098)/100 -> 0.034739851 | D26: =_xlfn.STDEV.S('Berelian assets'!I7:I1097)/100 -> 0.053348761

Sheet Charts
C73: دارایی | D73: ریسک سالانه | E73: CAGR
C74: کیان | D74: =Performance!B10 -> 0.26848908 | E74: =Performance!B9 -> 0.32571195
C75: دماوند | D75: =Performance!C10 -> 0.24105437 | E75: =Performance!C9 -> 0.36647083
C76: برلیان | D76: =Performance!D10 -> 0.24562501 | E76: =Performance!D9 -> 0.34949363
C77: شاخص کل | D77: =Performance!E10 -> 0.18354772 | E77: =Performance!E9 -> 0.4295381
A200: تاریخ | B200: کیان | C200: دماوند | D200: برلیان
A201: 45146 | B201: 0.953 | C201: 0.963 | D201: 0.9072
A202: 45147 | B202: 0.9529 | C202: 0.9627 | D202: 0.9121
A203: 45148 | B203: 0.953 | C203: 0.9627 | D203: 0.9121
A204: 45149 | B204: 0.953 | C204: 0.9627 | D204: 0.9121
A205: 45150 | B205: 0.9574 | C205: 0.9622 | D205: 0.8813
A206: 45151 | B206: 0.9584 | C206: 0.9653 | D206: 0.8824
A207: 45152 | B207: 0.9589 | C207: 0.9651 | D207: 0.8789
A208: 45153 | B208: 0.9592 | C208: 0.9647 | D208: 0.879
A209: 45154 | B209: 0.9669 | C209: 0.9664 | D209: 0.9024
A210: 45155 | B210: 0.967 | C210: 0.9664 | D210: 0.9024
A211: 45156 | B211: 0.967 | C211: 0.9664 | D211: 0.9024
A212: 45157 | B212: 0.9652 | C212: 0.9661 | D212: 0.9087
... A1296: 46241 | B1296: 0.9413 | C1296: 0.9522 | D1296: 0.9088

Sheet Report
A1: گزارش تحلیل عملکرد و مدیریت فعال پرتفوی سهام
A3: درس: تجزیه و تحلیل و مدیریت فعال پرتفوی سهام | مقطع کارشناسی ارشد مدیریت مالی | دوره: مرداد ۱۴۰۲ تا مرداد ۱۴۰۵ (۳ سال، ۶۵۶ روز معاملاتی) | دانشجو: محمدرضا شاهی | شماره دانشجویی: 432204011 | استاد: دکتر عیوضلو
A5: مقدمه، هدف و روش‌شناسی
A6: این گزارش عملکرد سه صندوق قابل معامله (ETF) بورس تهران — کیان، دماوند و برلیان — را در برابر شاخص کل به‌عنوان بنچمارک، طی بازه سه‌ساله مرداد ۱۴۰۲ تا مرداد ۱۴۰۵ (۶۵۶ مشاهده روزانه) بر مبنای مدل قیمت‌گذاری دارایی سرمایه‌ای (CAPM) و شاخص‌های استاندارد ارزیابی عملکرد پرتفوی مقایسه می‌کند.
A7: بازده روزانه به روش ساده محاسبه شده؛ سالانه‌سازی بازده با فرمول CAGR = (۱ + بازده تجمعی)^(252/n) - 1 و ریسک سالانه با ضرب انحراف معیار بازده روزانه در جذر ۲۵۲ انجام شده است. نرخ بازده بدون ریسک (Rf) به‌جای فرض ثابت اولیه، بر اساس میانگین وزنی نرخ بازده تا سررسید (YTM) اسناد خزانه اسلامی (اخزا) طی کل دوره تحلیل، وزن‌دهی‌شده بر مبنای حجم معاملات هر اخزا، محاسبه و برابر ۳۲.۴۶٪ سالانه به‌دست آمده که مبنای محاسبه شارپ، ترینر، آلفای جنسن و سورتینو در این گزارش است.
A9: خلاصه معیارهای بازدهی و ریسک
A10: معیار | B10: صندوق کیان | C10: صندوق دماوند | D10: صندوق برلیان | E10: شاخص کل
A11: بازده مرکب سالانه (CAGR) | B11: 32.57% | C11: 36.65% | D11: 34.95% | E11: 42.95%
A12: ریسک سالانه‌شده | B12: 26.85% | C12: 24.11% | D12: 24.56% | E12: 18.35%
A13: بتا (β) | B13: 1.20 | C13: 1.01 | D13: 1.01 | E13: 1.00
A14: نسبت شارپ | B14: 0.41% | C14: 17.37% | D14: 10.13% | E14: 57.17%
A15: نسبت ترینر | B15: 0.09% | C15: 4.13% | D15: 2.46% | E15: 10.49%
A16: آلفای جنسن (سالانه) | B16: -12.52% | C16: -6.46% | D16: -8.11% | E16: 0.00%
A17: Tracking Error (سالانه) | B17: 15.71% | C17: 15.30% | D17: 16.11% | E17: 0.00%
A18: نسبت اطلاعات (IR) | B18: -0.36 | C18: -0.22 | D18: -0.28 | E18: -
A19: نسبت سورتینو | B19: 0.45% | C19: 16.83% | D19: 10.24% | E19: 62.02%
A20: حداکثر افت سرمایه (MDD) | B20: -27.33% | C20: -26.89% | D20: -22.35% | E20: -26.34%
A22: تحلیل نسبت‌های محاسبه‌شده
A23: بازده و ریسک خام: شاخص کل با CAGR ۴۲.۹۵٪ و ریسک سالانه ۱۸.۳۵٪ بهترین بازده مطلق و کمترین نوسان را در بین چهار گزینه دارد. صندوق دماوند با CAGR ۳۶.۶۵٪ نزدیک‌ترین عملکرد به شاخص را ثبت کرده، در حالی که کیان با CAGR ۳۲.۵۷٪ و ریسک ۲۶.۸۵٪ (بالاترین ریسک میان صندوق‌ها) ضعیف‌ترین عملکرد مطلق را دارد.
A24: بتا و حساسیت به بازار: بتای کیان (۱.۲۰) نشان می‌دهد این صندوق نوسانات بازار را با ضریب تشدید بازتولید می‌کند؛ در مقابل دماوند (۱.۰۱) و برلیان (۱.۰۱) رفتار نزدیک به بازار دارند. بتای بالاتر از یک به‌تنهایی مطلوب نیست مگر با بازده تعدیل‌شده بالاتر همراه باشد که در مورد کیان چنین نیست.
A25: شارپ و ترینر با نرخ بدون ریسک اصلاح‌شده (۳۲.۴۶٪): با جایگزینی نرخ بدون ریسک ثابت با میانگین وزنی YTM اخزا، شارپ هر سه صندوق بسیار پایین اما مثبت شده است؛ شارپ کیان تنها ۰.۴۱٪ (ضعیف‌ترین)، برلیان ۱۰.۱۳٪ و دماوند ۱۷.۳۷٪ (بهترین میان صندوق‌ها) در برابر شارپ ۵۷.۱۷٪ شاخص کل. نسبت ترینر نیز دقیقاً همین رتبه‌بندی را با فاصله مشابه تکرار می‌کند و نشان می‌دهد حتی با نرخ بدون ریسک واقع‌بینانه‌تر، صندوق‌ها بازده کافی برای پوشش ریسک اضافی خود کسب نکرده‌اند.
A26: آلفای جنسن و مدیریت فعال: آلفای منفی هر سه صندوق (کیان ۱۲.۵۲-٪، برلیان ۸.۱۱-٪، دماوند ۶.۴۶-٪) نشان می‌دهد پس از تعدیل ریسک سیستماتیک (بتا) بر مبنای نرخ بدون ریسک جدید، همچنان هیچ‌کدام ارزش افزوده‌ای نسبت به بازار خلق نکرده‌اند؛ مدیریت فعال این صندوق‌ها در این بازه، بازدهی کمتر از حد انتظار CAPM ایجاد کرده است.
A27: نسبت اطلاعات و ریسک فعال: Information Ratio منفی برای هر سه صندوق (کیان ۰.۳۶-، برلیان ۰.۲۸-، دماوند ۰.۲۲-) بیانگر این است که ریسک فعال گرفته‌شده (Tracking Error حدود ۱۵ تا ۱۶ درصد) نتوانسته بازده فعال مثبتی نسبت به شاخص تولید کند؛ یعنی انحراف از بنچمارک برای سرمایه‌گذار زیان‌آور بوده، نه سودآور.
A28: سورتینو و ریسک نزولی: با نرخ بدون ریسک اصلاح‌شده، سورتینو دماوند (۱۶.۸۳٪) بهترین و کیان (۰.۴۵٪) ضعیف‌ترین است؛ برلیان با ۱۰.۲۴٪ در میانه قرار دارد. رتبه‌بندی سورتینو دقیقاً همان ترتیب شارپ را تکرار می‌کند، اما چون سورتینو فقط نوسان نامطلوب را در مخرج قرار می‌دهد، فاصله برلیان تا دماوند در این معیار کمی متفاوت از شارپ است.
A29: حداکثر افت سرمایه: برلیان با MDD ۲۲.۳۵-٪ کمترین افت را در میان همه (حتی کمتر از شاخص کل با ۲۶.۳۴-٪) ثبت کرده، در حالی که کیان با ۲۷.۳۳-٪ بدترین افت را تجربه کرده است؛ این تفاوت مستقیماً ریشه در سیاست تخصیص دارایی هر صندوق دارد که در بخش بعد بررسی می‌شود.
A31: ترکیب دارایی صندوق‌ها (میانگین سه‌ساله)
A32: معیار | B32: صندوق کیان | C32: صندوق دماوند | D32: صندوق برلیان
A33: سهم سهام (٪) | B33: 96.5% | C33: 95.7% | D33: 90.0%
A34: سهم نقد و سپرده بانکی (٪) | B34: 1.6% | C34: 0.6% | D34: 5.1%
A35: سهم اوراق مشارکت (٪) | B35: 0.0% | C35: 1.4% | D35: 0.8%
A36: سایر دارایی‌ها (٪) | B36: 3.7% | C36: 2.1% | D36: 2.3%
A37: نوسان‌پذیری تخصیص سهام (انحراف معیار) | B37: 2.51% | C37: 3.47% | D37: 5.33%
A39: اثر ترکیب دارایی بر بازدهی و ریسک
A40: کیان با ۹۶.۴۷٪ سهام و تنها ۱.۶۵٪ نقد، سیاست «همیشه در بازار» (Fully Invested) را دنبال می‌کند و عملاً هیچ بافر نقدی برای کاهش ضربه در روزهای منفی بازار ندارد؛ همین سیاست ساختاری مستقیماً با بالاترین بتا (۱.۲۰)، ضعیف‌ترین شارپ (۰.۴۱٪) و سورتینو (۰.۴۵٪)، و بدترین MDD (۲۷.۳۳-٪) این صندوق هم‌خوانی کامل دارد. به‌عبارت دیگر، ضعف عملکرد کیان حتی با نرخ بدون ریسک اصلاح‌شده (۳۲.۴۶٪) نیز ریشه در انتخاب سهم نیست، بلکه در نبود مدیریت فعال تخصیص دارایی است.
A41: برلیان با ۹۰.۰۳٪ سهام و ۵.۱۳٪ نقد (بیشترین بافر نقدی میان سه صندوق) و بالاترین نوسان‌پذیری تخصیص (۵.۳۳٪ انحراف معیار سهم سهام)، نشان‌دهنده سیاست فعال زمان‌بندی بازار (Market Timing) است؛ مدیر این صندوق به‌طور محسوس سهم نقد را در دوره‌های پرریسک افزایش داده که نتیجه آن کمترین حداکثر افت سرمایه (۲۲.۳۵-٪) در میان همه گزینه‌ها، حتی بهتر از شاخص کل، بوده است.
A42: دماوند با ۹۵.۷۲٪ سهام و کمترین سهم نقد (۰.۶۱٪) اما بتای نزدیک به بازار (۱.۰۱) و نوسان‌پذیری تخصیص متوسط (۳.۴۷٪)، بهترین بازده مطلق (CAGR ۳۶.۶۵٪) و بهترین شارپ (۱۷.۳۷٪) و سورتینو (۱۶.۸۳٪) را در میان سه صندوق کسب کرده است؛ این نشان می‌دهد صرفاً میزان نقد نگه‌داشته‌شده تعیین‌کننده عملکرد نیست، بلکه ترکیب مناسب دارایی‌های کم‌ریسک (مانند اوراق مشارکت ۱.۳۶٪) و زمان‌بندی مناسب ورود و خروج نیز نقش کلیدی دارد.
A43: در مجموع، رابطه معکوس بین سهم نقد و حداکثر افت سرمایه در این سه صندوق (کیان: کمترین نقد و بدترین افت؛ برلیان: بیشترین نقد و بهترین افت) به‌وضوح تأیید می‌کند که تخصیص دارایی، نه صرفاً انتخاب سهام، عامل اصلی تفاوت در مدیریت ریسک نزولی بین این صندوق‌ها بوده است.
A45: جمع‌بندی نهایی
A46: در این بازه سه‌ساله، هیچ‌یک از سه صندوق کیان، دماوند و برلیان نتوانسته‌اند بر شاخص کل غلبه کنند؛ شاخص کل با بازده مرکب سالانه ۴۲.۹۵٪، ریسک سالانه‌شده ۱۸.۳۵٪ و شارپ ۵۷.۱۷٪ (بر مبنای نرخ بدون ریسک اصلاح‌شده ۳۲.۴۶٪) بهترین ترکیب ریسک-بازده را در اختیار دارد.
A47: رتبه‌بندی نهایی صندوق‌ها بر اساس معیارهای تعدیل‌شده بر ریسک (شارپ، سورتینو، ترینر) با نرخ بدون ریسک جدید به این ترتیب است: دماوند (بهترین عملکرد نسبی با شارپ ۱۷.۳۷٪)، برلیان (شارپ ۱۰.۱۳٪) و در نهایت کیان (ضعیف‌ترین با شارپ ۰.۴۱٪). از منظر مدیریت ریسک نزولی (MDD)، برلیان با افت ۲۲.۳۵-٪ بهترین و کیان با افت ۲۷.۳۳-٪ بدترین عملکرد را ثبت کرده‌اند.
...
