Workbook
Name A: MonteCarlo02!$J$9:$K$10
Name mu: MonteCarlo02!$J$4:$K$4

Sheet Introduction
B1: پروژه درس مهندسی مالی و مدیریت ریسک
B2: استاد درس: دکتر فلاح‌پور
B4: دانشجو: | C4: محمدرضا شاهی
B7: شاخص مورد بررسی: شاخص بانک‌ها
B9: نیم‌سال اول سال تحصیلی 1405-1404

Sheet Parametric01
A1: تاریخ | B1: شاخص قیمت | C1: بازدهی
A2: 13990631 | B2: 8809
A3: 13990701 | B3: 8640.1 | C3: =LN(B3/B2) -> -0.019359769
A4: 13990702 | B4: 8759.6 | C4: =LN(B4/B3) -> 0.013736085
A5: 13990705 | B5: 8735.8 | C5: =LN(B5/B4) -> -0.0027207168
A6: 13990706 | B6: 8526.7 | C6: =LN(B6/B5) -> -0.024227108
A7: 13990707 | B7: 8158.8 | C7: =LN(B7/B6) -> -0.044105317
A8: 13990708 | B8: 7935.7 | C8: =LN(B8/B7) -> -0.027725532
A9: 13990709 | B9: 7966.4 | C9: =LN(B9/B8) -> 0.0038611301
A10: 13990712 | B10: 8310.6 | C10: =LN(B10/B9) -> 0.042299112
A11: 13990713 | B11: 8390.1 | C11: =LN(B11/B10) -> 0.0095206309
A12: 13990714 | B12: 8365.4 | C12: =LN(B12/B11) -> -0.0029482878
A13: 13990715 | B13: 8718.8 | C13: =LN(B13/B12) -> 0.041377462
A14: 13990716 | B14: 9037.1 | C14: =LN(B14/B13) -> 0.035856713
... A1187: 14040631 | B1187: 14857.7 | C1187: =LN(B1187/B1186) -> 0.022853508

Sheet Parametric02
A1: تاریخ | B1: شاخص قیمت | C1: بازدهی
A2: 13990631 | B2: 8809
A3: 13990701 | B3: 8640.1 | C3: =LN(B3/B2) -> -0.019359769 | E3: میانگین | F3: =AVERAGE(C3:C1187) -> 0.00044113445
A4: 13990702 | B4: 8759.6 | C4: =LN(B4/B3) -> 0.013736085 | E4: انحراف معیار | F4: =_xlfn.STDEV.S(C3:C1187) -> 0.016871784
A5: 13990705 | B5: 8735.8 | C5: =LN(B5/B4) -> -0.0027207168 | E5: چولگی | F5: =SKEW(C3:C1187) -> 0.076772779 | I5: بازه‌ها | J5: فراوانی | K5: درصد فراوانی | L5: توزیع فاصله‌ای نرمال | M5: توزیع تجمعی نرمال
A6: 13990706 | B6: 8526.7 | C6: =LN(B6/B5) -> -0.024227108 | E6: کشیدگی | F6: =KURT(C3:C1187) -> 0.80388875 | I6: -0.065 | J6: 1 | K6: =J6/COUNT($C$3:$C$1187) -> 0.00084388186 | L6: =_xlfn.NORM.DIST(I6,$F$3,$F$4,FALSE)*0.005 -> 6.3948943e-05 | M6: =_xlfn.NORM.DIST(I6,$F$3,$F$4,TRUE) -> 5.2501104e-05
A7: 13990707 | B7: 8158.8 | C7: =LN(B7/B6) -> -0.044105317 | E7: Max | F7: =MAX(C3:C1187) -> 0.054562292 | I7: -0.06 | J7: 0 | K7: =J7/COUNT($C$3:$C$1187) -> 0 | L7: =_xlfn.NORM.DIST(I7,$F$3,$F$4,FALSE)*0.005 -> 0.00019318448 | M7: =_xlfn.NORM.DIST(I7,$F$3,$F$4,TRUE) -> 0.0001702393
A8: 13990708 | B8: 7935.7 | C8: =LN(B8/B7) -> -0.027725532 | E8: Min | F8: =MIN(C3:C1187) -> -0.067718085 | I8: -0.055 | J8: 3 | K8: =J8/COUNT($C$3:$C$1187) -> 0.0025316456 | L8: =_xlfn.NORM.DIST(I8,$F$3,$F$4,FALSE)*0.005 -> 0.00053452647 | M8: =_xlfn.NORM.DIST(I8,$F$3,$F$4,TRUE) -> 0.00050805672
A9: 13990709 | B9: 7966.4 | C9: =LN(B9/B8) -> 0.0038611301 | I9: -0.05 | J9: 2 | K9: =J9/COUNT($C$3:$C$1187) -> 0.0016877637 | L9: =_xlfn.NORM.DIST(I9,$F$3,$F$4,FALSE)*0.005 -> 0.0013546412 | M9: =_xlfn.NORM.DIST(I9,$F$3,$F$4,TRUE) -> 0.0013963766
A10: 13990712 | B10: 8310.6 | C10: =LN(B10/B9) -> 0.042299112 | I10: -0.045 | J10: 2 | K10: =J10/COUNT($C$3:$C$1187) -> 0.0016877637 | L10: =_xlfn.NORM.DIST(I10,$F$3,$F$4,FALSE)*0.005 -> 0.0031443976 | M10: =_xlfn.NORM.DIST(I10,$F$3,$F$4,TRUE) -> 0.0035372034
A11: 13990713 | B11: 8390.1 | C11: =LN(B11/B10) -> 0.0095206309 | I11: -0.04 | J11: 6 | K11: =J11/COUNT($C$3:$C$1187) -> 0.0050632911 | L11: =_xlfn.NORM.DIST(I11,$F$3,$F$4,FALSE)*0.005 -> 0.0066851128 | M11: =_xlfn.NORM.DIST(I11,$F$3,$F$4,TRUE) -> 0.008265673
A12: 13990714 | B12: 8365.4 | C12: =LN(B12/B11) -> -0.0029482878 | I12: -0.035 | J12: 6 | K12: =J12/COUNT($C$3:$C$1187) -> 0.0050632911 | L12: =_xlfn.NORM.DIST(I12,$F$3,$F$4,FALSE)*0.005 -> 0.013017816 | M12: =_xlfn.NORM.DIST(I12,$F$3,$F$4,TRUE) -> 0.017837357
A13: 13990715 | B13: 8718.8 | C13: =LN(B13/B12) -> 0.041377462 | I13: -0.03 | J13: 23 | K13: =J13/COUNT($C$3:$C$1187) -> 0.019409283 | L13: =_xlfn.NORM.DIST(I13,$F$3,$F$4,FALSE)*0.005 -> 0.023218042 | M13: =_xlfn.NORM.DIST(I13,$F$3,$F$4,TRUE) -> 0.035595049
A14: 13990716 | B14: 9037.1 | C14: =LN(B14/B13) -> 0.035856713 | I14: -0.025 | J14: 30 | K14: =J14/COUNT($C$3:$C$1187) -> 0.025316456 | L14: =_xlfn.NORM.DIST(I14,$F$3,$F$4,FALSE)*0.005 -> 0.037928981 | M14: =_xlfn.NORM.DIST(I14,$F$3,$F$4,TRUE) -> 0.065788762
A15: 13990719 | B15: 9242.3 | C15: =LN(B15/B14) -> 0.022452446 | I15: -0.02 | J15: 42 | K15: =J15/COUNT($C$3:$C$1187) -> 0.035443038 | L15: =_xlfn.NORM.DIST(I15,$F$3,$F$4,FALSE)*0.005 -> 0.056751176 | M15: =_xlfn.NORM.DIST(I15,$F$3,$F$4,TRUE) -> 0.11284093
A16: 13990720 | B16: 9677.5 | C16: =LN(B16/B15) -> 0.046012831 | I16: -0.015 | J16: 61 | K16: =J16/COUNT($C$3:$C$1187) -> 0.051476793 | L16: =_xlfn.NORM.DIST(I16,$F$3,$F$4,FALSE)*0.005 -> 0.077774396 | M16: =_xlfn.NORM.DIST(I16,$F$3,$F$4,TRUE) -> 0.18004211
A17: 13990721 | B17: 9450.3 | C17: =LN(B17/B16) -> -0.023757116 | I17: -0.01 | J17: 91 | K17: =J17/COUNT($C$3:$C$1187) -> 0.076793249 | L17: =_xlfn.NORM.DIST(I17,$F$3,$F$4,FALSE)*0.005 -> 0.097623986 | M17: =_xlfn.NORM.DIST(I17,$F$3,$F$4,TRUE) -> 0.26800699
A18: 13990722 | B18: 9303.1 | C18: =LN(B18/B17) -> -0.015698809 | I18: -0.005 | J18: 143 | K18: =J18/COUNT($C$3:$C$1187) -> 0.12067511 | L18: =_xlfn.NORM.DIST(I18,$F$3,$F$4,FALSE)*0.005 -> 0.11223661 | M18: =_xlfn.NORM.DIST(I18,$F$3,$F$4,TRUE) -> 0.37353733
A19: 13990723 | B19: 9101.3 | C19: =LN(B19/B18) -> -0.021930417 | I19: -1.2143064e-17 | J19: 224 | K19: =J19/COUNT($C$3:$C$1187) -> 0.18902954 | L19: =_xlfn.NORM.DIST(I19,$F$3,$F$4,FALSE)*0.005 -> 0.11818725 | M19: =_xlfn.NORM.DIST(I19,$F$3,$F$4,TRUE) -> 0.48957033
A20: 13990727 | B20: 8738.6 | C20: =LN(B20/B19) -> -0.040667267 | I20: 0.005 | J20: 156 | K20: =J20/COUNT($C$3:$C$1187) -> 0.13164557 | L20: =_xlfn.NORM.DIST(I20,$F$3,$F$4,FALSE)*0.005 -> 0.11398949 | M20: =_xlfn.NORM.DIST(I20,$F$3,$F$4,TRUE) -> 0.6064993
... A30: 13990812 | B30: 7300.5 | C30: =LN(B30/B29) -> -0.0081714401 | I30: 0.055 | J30: 4 | K30: =J30/COUNT($C$3:$C$1187) -> 0.0033755274 | L30: =_xlfn.NORM.DIST(I30,$F$3,$F$4,FALSE)*0.005 -> 0.00063387309 | M30: =_xlfn.NORM.DIST(I30,$F$3,$F$4,TRUE) -> 0.99938908
A31: 13990814 | B31: 7353.6 | C31: =LN(B31/B30) -> 0.0072471503 | K31: =SUM(K6:K30) -> 1 | L31: =SUM(L6:L30) -> 0.9996294
A32: 13990817 | B32: 7191.6 | C32: =LN(B32/B31) -> -0.022276311
A33: 13990818 | B33: 6975.4 | C33: =LN(B33/B32) -> -0.030524005
A34: 13990819 | B34: 6769.1 | C34: =LN(B34/B33) -> -0.030021535
A35: 13990820 | B35: 6707.4 | C35: =LN(B35/B34) -> -0.0091567441
A36: 13990821 | B36: 6729.8 | C36: =LN(B36/B35) -> 0.003334031
A37: 13990824 | B37: 6975.6 | C37: =LN(B37/B36) -> 0.03587292
A38: 13990825 | B38: 7146.4 | C38: =LN(B38/B37) -> 0.024190388
A39: 13990826 | B39: 7348 | C39: =LN(B39/B38) -> 0.027819434
A40: 13990827 | B40: 7599.1 | C40: =LN(B40/B39) -> 0.033601652
A41: 13990828 | B41: 7881.3 | C41: =LN(B41/B40) -> 0.036463046
A42: 13990901 | B42: 8038 | C42: =LN(B42/B41) -> 0.019687431
A43: 13990902 | B43: 8028.2 | C43: =LN(B43/B42) -> -0.0012199526
... A1187: 14040631 | B1187: 14857.7 | C1187: =LN(B1187/B1186) -> 0.022853508

Sheet Parametric03
A1: تاریخ | B1: شاخص قیمت | C1: بازدهی | D1: Lag | E1: خودهمبستگی بازدهی
A2: 13990631 | B2: 8809 | D2: 1 | E2: =CORREL($C$3:$C$1188,C4:C1189) -> 0.30625196
A3: 13990701 | B3: 8640.1 | C3: =LN(B3/B2) -> -0.019359769 | D3: 2 | E3: =CORREL($C$3:$C$1188,C5:C1190) -> 0.035229429
A4: 13990702 | B4: 8759.6 | C4: =LN(B4/B3) -> 0.013736085 | D4: 3 | E4: =CORREL($C$3:$C$1188,C6:C1191) -> 0.085737916
A5: 13990705 | B5: 8735.8 | C5: =LN(B5/B4) -> -0.0027207168 | D5: 4 | E5: =CORREL($C$3:$C$1188,C7:C1192) -> 0.030948014
A6: 13990706 | B6: 8526.7 | C6: =LN(B6/B5) -> -0.024227108 | D6: 5 | E6: =CORREL($C$3:$C$1188,C8:C1193) -> -0.0053634237
A7: 13990707 | B7: 8158.8 | C7: =LN(B7/B6) -> -0.044105317 | D7: 6 | E7: =CORREL($C$3:$C$1188,C9:C1194) -> -0.0038040371
A8: 13990708 | B8: 7935.7 | C8: =LN(B8/B7) -> -0.027725532 | D8: 7 | E8: =CORREL($C$3:$C$1188,C10:C1195) -> 0.03052721
A9: 13990709 | B9: 7966.4 | C9: =LN(B9/B8) -> 0.0038611301 | D9: 8 | E9: =CORREL($C$3:$C$1188,C11:C1196) -> -0.014343245
A10: 13990712 | B10: 8310.6 | C10: =LN(B10/B9) -> 0.042299112 | D10: 9 | E10: =CORREL($C$3:$C$1188,C12:C1197) -> -0.027340231
A11: 13990713 | B11: 8390.1 | C11: =LN(B11/B10) -> 0.0095206309 | D11: 10 | E11: =CORREL($C$3:$C$1188,C13:C1198) -> 0.0025970137
A12: 13990714 | B12: 8365.4 | C12: =LN(B12/B11) -> -0.0029482878 | D12: 11 | E12: =CORREL($C$3:$C$1188,C14:C1199) -> -0.021189507
A13: 13990715 | B13: 8718.8 | C13: =LN(B13/B12) -> 0.041377462 | D13: 12 | E13: =CORREL($C$3:$C$1188,C15:C1200) -> -0.0024829302
A14: 13990716 | B14: 9037.1 | C14: =LN(B14/B13) -> 0.035856713 | D14: 13 | E14: =CORREL($C$3:$C$1188,C16:C1201) -> 0.041306435
... A101: 13991126 | B101: 7471.3 | C101: =LN(B101/B100) -> -0.0096570204 | D101: 100 | E101: =CORREL($C$3:$C$1188,C103:C1288) -> -0.01845716
A102: 13991127 | B102: 7399 | C102: =LN(B102/B101) -> -0.0097241575
A103: 13991128 | B103: 7300.4 | C103: =LN(B103/B102) -> -0.013415715
A104: 13991129 | B104: 7261.6 | C104: =LN(B104/B103) -> -0.0053289509
A105: 13991202 | B105: 7230.8 | C105: =LN(B105/B104) -> -0.0042505101
A106: 13991203 | B106: 7191.7 | C106: =LN(B106/B105) -> -0.0054220968
A107: 13991204 | B107: 7148 | C107: =LN(B107/B106) -> -0.006094986
A108: 13991205 | B108: 7070.6 | C108: =LN(B108/B107) -> -0.010887255
A109: 13991206 | B109: 6984.9 | C109: =LN(B109/B108) -> -0.012194666
A110: 13991209 | B110: 6882.8 | C110: =LN(B110/B109) -> -0.01472513
A111: 13991210 | B111: 6850.2 | C111: =LN(B111/B110) -> -0.004747697
A112: 13991211 | B112: 6795 | C112: =LN(B112/B111) -> -0.0080908013
A113: 13991212 | B113: 6764.5 | C113: =LN(B113/B112) -> -0.0044986985
... A1187: 14040631 | B1187: 14857.7 | C1187: =LN(B1187/B1186) -> 0.022853508

Sheet Parametric04
A1: تاریخ | B1: شاخص قیمت | C1: بازدهی | D1: مجذور بازدهی | E1: Lag | F1: خودهمبستگی مجذور بازدهی
A2: 13990631 | B2: 8809 | E2: 1 | F2: =CORREL($D$3:$D$1187,D4:D1188) -> 0.21902999
A3: 13990701 | B3: 8640.1 | C3: =LN(B3/B2) -> -0.019359769 | D3: =C3^2 -> 0.00037480067 | E3: 2 | F3: =CORREL($D$3:$D$1187,D5:D1189) -> 0.17285265
A4: 13990702 | B4: 8759.6 | C4: =LN(B4/B3) -> 0.013736085 | D4: =C4^2 -> 0.00018868003 | E4: 3 | F4: =CORREL($D$3:$D$1187,D6:D1190) -> 0.18368901
A5: 13990705 | B5: 8735.8 | C5: =LN(B5/B4) -> -0.0027207168 | D5: =C5^2 -> 7.4023001e-06 | E5: 4 | F5: =CORREL($D$3:$D$1187,D7:D1191) -> 0.13800287
A6: 13990706 | B6: 8526.7 | C6: =LN(B6/B5) -> -0.024227108 | D6: =C6^2 -> 0.00058695277 | E6: 5 | F6: =CORREL($D$3:$D$1187,D8:D1192) -> 0.15985483
A7: 13990707 | B7: 8158.8 | C7: =LN(B7/B6) -> -0.044105317 | D7: =C7^2 -> 0.001945279 | E7: 6 | F7: =CORREL($D$3:$D$1187,D9:D1193) -> 0.16889442
A8: 13990708 | B8: 7935.7 | C8: =LN(B8/B7) -> -0.027725532 | D8: =C8^2 -> 0.00076870515 | E8: 7 | F8: =CORREL($D$3:$D$1187,D10:D1194) -> 0.096185724
A9: 13990709 | B9: 7966.4 | C9: =LN(B9/B8) -> 0.0038611301 | D9: =C9^2 -> 1.4908325e-05 | E9: 8 | F9: =CORREL($D$3:$D$1187,D11:D1195) -> 0.10321363
A10: 13990712 | B10: 8310.6 | C10: =LN(B10/B9) -> 0.042299112 | D10: =C10^2 -> 0.0017892148 | E10: 9 | F10: =CORREL($D$3:$D$1187,D12:D1196) -> 0.14122522
A11: 13990713 | B11: 8390.1 | C11: =LN(B11/B10) -> 0.0095206309 | D11: =C11^2 -> 9.0642413e-05 | E11: 10 | F11: =CORREL($D$3:$D$1187,D13:D1197) -> 0.088595432
A12: 13990714 | B12: 8365.4 | C12: =LN(B12/B11) -> -0.0029482878 | D12: =C12^2 -> 8.6924008e-06 | E12: 11 | F12: =CORREL($D$3:$D$1187,D14:D1198) -> 0.13967438
A13: 13990715 | B13: 8718.8 | C13: =LN(B13/B12) -> 0.041377462 | D13: =C13^2 -> 0.0017120944 | E13: 12 | F13: =CORREL($D$3:$D$1187,D15:D1199) -> 0.08654713
A14: 13990716 | B14: 9037.1 | C14: =LN(B14/B13) -> 0.035856713 | D14: =C14^2 -> 0.0012857038 | E14: 13 | F14: =CORREL($D$3:$D$1187,D16:D1200) -> 0.10066652
... A101: 13991126 | B101: 7471.3 | C101: =LN(B101/B100) -> -0.0096570204 | D101: =C101^2 -> 9.3258043e-05 | E101: 100 | F101: =CORREL($D$3:$D$1187,D103:D1287) -> -0.047492217
A102: 13991127 | B102: 7399 | C102: =LN(B102/B101) -> -0.0097241575 | D102: =C102^2 -> 9.4559239e-05
A103: 13991128 | B103: 7300.4 | C103: =LN(B103/B102) -> -0.013415715 | D103: =C103^2 -> 0.0001799814
A104: 13991129 | B104: 7261.6 | C104: =LN(B104/B103) -> -0.0053289509 | D104: =C104^2 -> 2.8397718e-05
A105: 13991202 | B105: 7230.8 | C105: =LN(B105/B104) -> -0.0042505101 | D105: =C105^2 -> 1.8066836e-05
A106: 13991203 | B106: 7191.7 | C106: =LN(B106/B105) -> -0.0054220968 | D106: =C106^2 -> 2.9399134e-05
A107: 13991204 | B107: 7148 | C107: =LN(B107/B106) -> -0.006094986 | D107: =C107^2 -> 3.7148854e-05
A108: 13991205 | B108: 7070.6 | C108: =LN(B108/B107) -> -0.010887255 | D108: =C108^2 -> 0.00011853233
A109: 13991206 | B109: 6984.9 | C109: =LN(B109/B108) -> -0.012194666 | D109: =C109^2 -> 0.00014870987
A110: 13991209 | B110: 6882.8 | C110: =LN(B110/B109) -> -0.01472513 | D110: =C110^2 -> 0.00021682946
A111: 13991210 | B111: 6850.2 | C111: =LN(B111/B110) -> -0.004747697 | D111: =C111^2 -> 2.2540627e-05
A112: 13991211 | B112: 6795 | C112: =LN(B112/B111) -> -0.0080908013 | D112: =C112^2 -> 6.5461066e-05
A113: 13991212 | B113: 6764.5 | C113: =LN(B113/B112) -> -0.0044986985 | D113: =C113^2 -> 2.0238289e-05
... A1187: 14040631 | B1187: 14857.7 | C1187: =LN(B1187/B1186) -> 0.022853508 | D1187: =C1187^2 -> 0.00052228285

Sheet Parametric05
A1: تاریخ | B1: شاخص قیمت | C1: بازدهی 1 | D1: بازدهی 5 | E1: بازدهی 10 | F1: بازدهی 15
A2: 13990631 | B2: 8809 | I2: بازدهی 1 | J2: بازدهی 5 | K2: بازدهی 10 | L2: بازدهی 15
A3: 13990701 | B3: 8640.1 | C3: =LN(B3/B2) -> -0.019359769 | H3: میانگین | I3: =AVERAGE(C3:C1187) -> 0.00044113445 | J3: =AVERAGE(D3:D1187) -> 0.0023618365 | K3: =AVERAGE(E3:E1187) -> 0.0045122846 | L3: =AVERAGE(F3:F1187) -> 0.0070855094
A4: 13990702 | B4: 8759.6 | C4: =LN(B4/B3) -> 0.013736085 | H4: انحراف معیار | I4: =_xlfn.STDEV.S(C3:C1187) -> 0.016871784 | J4: =_xlfn.STDEV.S(D3:D1187) -> 0.049546584 | K4: =_xlfn.STDEV.S(E3:E1187) -> 0.068821691 | L4: =_xlfn.STDEV.S(F3:F1187) -> 0.09172477
A5: 13990705 | B5: 8735.8 | C5: =LN(B5/B4) -> -0.0027207168 | H5: چولگی | I5: =SKEW(C3:C1187) -> 0.076772779 | J5: =SKEW(D3:D1187) -> 0.13888881 | K5: =SKEW(E3:E1187) -> 0.15693851 | L5: =SKEW(F3:F1187) -> 0.37424502
A6: 13990706 | B6: 8526.7 | C6: =LN(B6/B5) -> -0.024227108 | H6: کشیدگی | I6: =KURT(C3:C1187) -> 0.80388875 | J6: =KURT(D3:D1187) -> 1.0952917 | K6: =KURT(E3:E1187) -> -0.098356918 | L6: =KURT(F3:F1187) -> 1.2644491
A7: 13990707 | B7: 8158.8 | C7: =LN(B7/B6) -> -0.044105317 | D7: =LN(B7/B2) -> -0.076676827
A8: 13990708 | B8: 7935.7 | C8: =LN(B8/B7) -> -0.027725532
A9: 13990709 | B9: 7966.4 | C9: =LN(B9/B8) -> 0.0038611301
A10: 13990712 | B10: 8310.6 | C10: =LN(B10/B9) -> 0.042299112
A11: 13990713 | B11: 8390.1 | C11: =LN(B11/B10) -> 0.0095206309
A12: 13990714 | B12: 8365.4 | C12: =LN(B12/B11) -> -0.0029482878 | D12: =LN(B12/B7) -> 0.025007052 | E12: =LN(B12/B2) -> -0.051669775
A13: 13990715 | B13: 8718.8 | C13: =LN(B13/B12) -> 0.041377462
A14: 13990716 | B14: 9037.1 | C14: =LN(B14/B13) -> 0.035856713
A15: 13990719 | B15: 9242.3 | C15: =LN(B15/B14) -> 0.022452446
A16: 13990720 | B16: 9677.5 | C16: =LN(B16/B15) -> 0.046012831
A17: 13990721 | B17: 9450.3 | C17: =LN(B17/B16) -> -0.023757116 | D17: =LN(B17/B12) -> 0.12194234 | F17: =LN(B17/B2) -> 0.070272561
A18: 13990722 | B18: 9303.1 | C18: =LN(B18/B17) -> -0.015698809
A19: 13990723 | B19: 9101.3 | C19: =LN(B19/B18) -> -0.021930417
A20: 13990727 | B20: 8738.6 | C20: =LN(B20/B19) -> -0.040667267
A21: 13990728 | B21: 8376.2 | C21: =LN(B21/B20) -> -0.042355643
A22: 13990729 | B22: 8003.5 | C22: =LN(B22/B21) -> -0.045515405 | D22: =LN(B22/B17) -> -0.16616754 | E22: =LN(B22/B12) -> -0.044225206
A23: 13990730 | B23: 8247.8 | C23: =LN(B23/B22) -> 0.030067552
A24: 13990803 | B24: 7949 | C24: =LN(B24/B23) -> -0.036900364
A25: 13990805 | B25: 7659 | C25: =LN(B25/B24) -> -0.037164708
A26: 13990806 | B26: 7459.5 | C26: =LN(B26/B25) -> -0.026393039
A27: 13990807 | B27: 7307.3 | C27: =LN(B27/B26) -> -0.020614539 | D27: =LN(B27/B22) -> -0.091005098
A28: 13990810 | B28: 7538.9 | C28: =LN(B28/B27) -> 0.031202434
A29: 13990811 | B29: 7360.4 | C29: =LN(B29/B28) -> -0.023962004
A30: 13990812 | B30: 7300.5 | C30: =LN(B30/B29) -> -0.0081714401
A31: 13990814 | B31: 7353.6 | C31: =LN(B31/B30) -> 0.0072471503
A32: 13990817 | B32: 7191.6 | C32: =LN(B32/B31) -> -0.022276311 | D32: =LN(B32/B27) -> -0.01596017 | E32: =LN(B32/B22) -> -0.10696527 | F32: =LN(B32/B17) -> -0.27313281
A33: 13990818 | B33: 6975.4 | C33: =LN(B33/B32) -> -0.030524005
A34: 13990819 | B34: 6769.1 | C34: =LN(B34/B33) -> -0.030021535
A35: 13990820 | B35: 6707.4 | C35: =LN(B35/B34) -> -0.0091567441
A36: 13990821 | B36: 6729.8 | C36: =LN(B36/B35) -> 0.003334031
A37: 13990824 | B37: 6975.6 | C37: =LN(B37/B36) -> 0.03587292 | D37: =LN(B37/B32) -> -0.030495333
A38: 13990825 | B38: 7146.4 | C38: =LN(B38/B37) -> 0.024190388
A39: 13990826 | B39: 7348 | C39: =LN(B39/B38) -> 0.027819434
A40: 13990827 | B40: 7599.1 | C40: =LN(B40/B39) -> 0.033601652
...

Sheet SMA
A1: تاریخ | B1: شاخص قیمت | C1: بازدهی | D1: مجذور بازدهی | E1: میانگین متحرک 25 | F1: میانگین متحرک 50 | G1: میانگین متحرک 100
A2: 13990631 | B2: 8809
A3: 13990701 | B3: 8640.1 | C3: =LN(B3/B2) -> -0.019359769 | D3: =C3^2 -> 0.00037480067
A4: 13990702 | B4: 8759.6 | C4: =LN(B4/B3) -> 0.013736085 | D4: =C4^2 -> 0.00018868003
A5: 13990705 | B5: 8735.8 | C5: =LN(B5/B4) -> -0.0027207168 | D5: =C5^2 -> 7.4023001e-06
A6: 13990706 | B6: 8526.7 | C6: =LN(B6/B5) -> -0.024227108 | D6: =C6^2 -> 0.00058695277
A7: 13990707 | B7: 8158.8 | C7: =LN(B7/B6) -> -0.044105317 | D7: =C7^2 -> 0.001945279
A8: 13990708 | B8: 7935.7 | C8: =LN(B8/B7) -> -0.027725532 | D8: =C8^2 -> 0.00076870515
A9: 13990709 | B9: 7966.4 | C9: =LN(B9/B8) -> 0.0038611301 | D9: =C9^2 -> 1.4908325e-05
A10: 13990712 | B10: 8310.6 | C10: =LN(B10/B9) -> 0.042299112 | D10: =C10^2 -> 0.0017892148
A11: 13990713 | B11: 8390.1 | C11: =LN(B11/B10) -> 0.0095206309 | D11: =C11^2 -> 9.0642413e-05
A12: 13990714 | B12: 8365.4 | C12: =LN(B12/B11) -> -0.0029482878 | D12: =C12^2 -> 8.6924008e-06
A13: 13990715 | B13: 8718.8 | C13: =LN(B13/B12) -> 0.041377462 | D13: =C13^2 -> 0.0017120944
A14: 13990716 | B14: 9037.1 | C14: =LN(B14/B13) -> 0.035856713 | D14: =C14^2 -> 0.0012857038
... A27: 13990807 | B27: 7307.3 | C27: =LN(B27/B26) -> -0.020614539 | D27: =C27^2 -> 0.00042495923
A28: 13990810 | B28: 7538.9 | C28: =LN(B28/B27) -> 0.031202434 | D28: =C28^2 -> 0.00097359191 | E28: =SQRT(AVERAGE(D3:D27)) -> 0.030314423
A29: 13990811 | B29: 7360.4 | C29: =LN(B29/B28) -> -0.023962004 | D29: =C29^2 -> 0.00057417762 | E29: =SQRT(AVERAGE(D4:D28)) -> 0.030706936
A30: 13990812 | B30: 7300.5 | C30: =LN(B30/B29) -> -0.0081714401 | D30: =C30^2 -> 6.6772434e-05 | E30: =SQRT(AVERAGE(D5:D29)) -> 0.030956999
A31: 13990814 | B31: 7353.6 | C31: =LN(B31/B30) -> 0.0072471503 | D31: =C31^2 -> 5.2521187e-05 | E31: =SQRT(AVERAGE(D6:D30)) -> 0.030995332
A32: 13990817 | B32: 7191.6 | C32: =LN(B32/B31) -> -0.022276311 | D32: =C32^2 -> 0.00049623403 | E32: =SQRT(AVERAGE(D7:D31)) -> 0.030648546
A33: 13990818 | B33: 6975.4 | C33: =LN(B33/B32) -> -0.030524005 | D33: =C33^2 -> 0.00093171485 | E33: =SQRT(AVERAGE(D8:D32)) -> 0.029687902
A34: 13990819 | B34: 6769.1 | C34: =LN(B34/B33) -> -0.030021535 | D34: =C34^2 -> 0.00090129257 | E34: =SQRT(AVERAGE(D9:D33)) -> 0.029797516
A35: 13990820 | B35: 6707.4 | C35: =LN(B35/B34) -> -0.0091567441 | D35: =C35^2 -> 8.3845963e-05 | E35: =SQRT(AVERAGE(D10:D34)) -> 0.03038663
A36: 13990821 | B36: 6729.8 | C36: =LN(B36/B35) -> 0.003334031 | D36: =C36^2 -> 1.1115763e-05 | E36: =SQRT(AVERAGE(D11:D35)) -> 0.02924265
A37: 13990824 | B37: 6975.6 | C37: =LN(B37/B36) -> 0.03587292 | D37: =C37^2 -> 0.0012868664 | E37: =SQRT(AVERAGE(D12:D36)) -> 0.029188208
A38: 13990825 | B38: 7146.4 | C38: =LN(B38/B37) -> 0.024190388 | D38: =C38^2 -> 0.00058517487 | E38: =SQRT(AVERAGE(D13:D37)) -> 0.030051264
A39: 13990826 | B39: 7348 | C39: =LN(B39/B38) -> 0.027819434 | D39: =C39^2 -> 0.00077392091 | E39: =SQRT(AVERAGE(D14:D38)) -> 0.029291665
... A52: 13990915 | B52: 9208.2 | C52: =LN(B52/B51) -> 0.0055211758 | D52: =C52^2 -> 3.0483382e-05 | E52: =SQRT(AVERAGE(D27:D51)) -> 0.024416443
A53: 13990916 | B53: 9183.8 | C53: =LN(B53/B52) -> -0.0026533291 | D53: =C53^2 -> 7.0401553e-06 | E53: =SQRT(AVERAGE(D28:D52)) -> 0.024091153 | F53: =SQRT(AVERAGE(D3:D52)) -> 0.027380174
A54: 13990917 | B54: 9294.2 | C54: =LN(B54/B53) -> 0.011949487 | D54: =C54^2 -> 0.00014279025 | E54: =SQRT(AVERAGE(D29:D53)) -> 0.023274913 | F54: =SQRT(AVERAGE(D4:D53)) -> 0.027245527
A55: 13990918 | B55: 9299.6 | C55: =LN(B55/B54) -> 0.00058083879 | D55: =C55^2 -> 3.373737e-07 | E55: =SQRT(AVERAGE(D30:D54)) -> 0.022901224 | F55: =SQRT(AVERAGE(D5:D54)) -> 0.027228679
A56: 13990919 | B56: 9173.8 | C56: =LN(B56/B55) -> -0.013619793 | D56: =C56^2 -> 0.00018549877 | E56: =SQRT(AVERAGE(D31:D55)) -> 0.022843132 | F56: =SQRT(AVERAGE(D6:D55)) -> 0.027226084
A57: 13990922 | B57: 9235.5 | C57: =LN(B57/B56) -> 0.0067031588 | D57: =C57^2 -> 4.4932338e-05 | E57: =SQRT(AVERAGE(D32:D56)) -> 0.022959263 | F57: =SQRT(AVERAGE(D7:D56)) -> 0.02707823
A58: 13990923 | B58: 9108.9 | C58: =LN(B58/B57) -> -0.013802796 | D58: =C58^2 -> 0.00019051719 | E58: =SQRT(AVERAGE(D33:D57)) -> 0.022562706 | F58: =SQRT(AVERAGE(D8:D57)) -> 0.026367094
A59: 13990924 | B59: 9183.5 | C59: =LN(B59/B58) -> 0.008156438 | D59: =C59^2 -> 6.6527481e-05 | E59: =SQRT(AVERAGE(D34:D58)) -> 0.02189584 | F59: =SQRT(AVERAGE(D9:D58)) -> 0.02614689
A60: 13990925 | B60: 8818.1 | C60: =LN(B60/B59) -> -0.040601968 | D60: =C60^2 -> 0.0016485198 | E60: =SQRT(AVERAGE(D35:D59)) -> 0.021119593 | F60: =SQRT(AVERAGE(D10:D59)) -> 0.026166625
A61: 13990926 | B61: 8562.9 | C61: =LN(B61/B60) -> -0.029367509 | D61: =C61^2 -> 0.00086245061 | E61: =SQRT(AVERAGE(D36:D60)) -> 0.022552697 | F61: =SQRT(AVERAGE(D11:D60)) -> 0.026112801
A62: 13990929 | B62: 8585.9 | C62: =LN(B62/B61) -> 0.002682405 | D62: =C62^2 -> 7.1952968e-06 | E62: =SQRT(AVERAGE(D37:D61)) -> 0.02329544 | F62: =SQRT(AVERAGE(D12:D61)) -> 0.026406713
A63: 13990930 | B63: 8348.6 | C63: =LN(B63/B62) -> -0.028027463 | D63: =C63^2 -> 0.00078553867 | E63: =SQRT(AVERAGE(D38:D62)) -> 0.02216959 | F63: =SQRT(AVERAGE(D13:D62)) -> 0.026406147
A64: 13991001 | B64: 8319.1 | C64: =LN(B64/B63) -> -0.0035397842 | D64: =C64^2 -> 1.2530072e-05 | E64: =SQRT(AVERAGE(D39:D63)) -> 0.022349614 | F64: =SQRT(AVERAGE(D14:D63)) -> 0.026052897
...

Sheet VaR01
A1: تاریخ | B1: شاخص قیمت | C1: بازدهی | D1: مجذور بازدهی | E1: ارزش دارایی | F1: میانگین متحرک 25 | G1: VaR 25 | H1: میانگین متحرک 50 | I1: VaR 50 | J1: میانگین متحرک 100 | K1: VaR 100 | L1: VaR Simple
A2: 13990631 | B2: 8809
A3: 13990701 | B3: 8640.1 | C3: =LN(B3/B2) -> -0.019359769 | D3: =C3^2 -> 0.00037480067
A4: 13990702 | B4: 8759.6 | C4: =LN(B4/B3) -> 0.013736085 | D4: =C4^2 -> 0.00018868003
A5: 13990705 | B5: 8735.8 | C5: =LN(B5/B4) -> -0.0027207168 | D5: =C5^2 -> 7.4023001e-06
A6: 13990706 | B6: 8526.7 | C6: =LN(B6/B5) -> -0.024227108 | D6: =C6^2 -> 0.00058695277
A7: 13990707 | B7: 8158.8 | C7: =LN(B7/B6) -> -0.044105317 | D7: =C7^2 -> 0.001945279
A8: 13990708 | B8: 7935.7 | C8: =LN(B8/B7) -> -0.027725532 | D8: =C8^2 -> 0.00076870515
A9: 13990709 | B9: 7966.4 | C9: =LN(B9/B8) -> 0.0038611301 | D9: =C9^2 -> 1.4908325e-05
A10: 13990712 | B10: 8310.6 | C10: =LN(B10/B9) -> 0.042299112 | D10: =C10^2 -> 0.0017892148
A11: 13990713 | B11: 8390.1 | C11: =LN(B11/B10) -> 0.0095206309 | D11: =C11^2 -> 9.0642413e-05
A12: 13990714 | B12: 8365.4 | C12: =LN(B12/B11) -> -0.0029482878 | D12: =C12^2 -> 8.6924008e-06
A13: 13990715 | B13: 8718.8 | C13: =LN(B13/B12) -> 0.041377462 | D13: =C13^2 -> 0.0017120944
A14: 13990716 | B14: 9037.1 | C14: =LN(B14/B13) -> 0.035856713 | D14: =C14^2 -> 0.0012857038
... A27: 13990807 | B27: 7307.3 | C27: =LN(B27/B26) -> -0.020614539 | D27: =C27^2 -> 0.00042495923
A28: 13990810 | B28: 7538.9 | C28: =LN(B28/B27) -> 0.031202434 | D28: =C28^2 -> 0.00097359191 | F28: =SQRT(AVERAGE(D3:D27)) -> 0.030314423
A29: 13990811 | B29: 7360.4 | C29: =LN(B29/B28) -> -0.023962004 | D29: =C29^2 -> 0.00057417762 | F29: =SQRT(AVERAGE(D4:D28)) -> 0.030706936
A30: 13990812 | B30: 7300.5 | C30: =LN(B30/B29) -> -0.0081714401 | D30: =C30^2 -> 6.6772434e-05 | F30: =SQRT(AVERAGE(D5:D29)) -> 0.030956999
A31: 13990814 | B31: 7353.6 | C31: =LN(B31/B30) -> 0.0072471503 | D31: =C31^2 -> 5.2521187e-05 | F31: =SQRT(AVERAGE(D6:D30)) -> 0.030995332
A32: 13990817 | B32: 7191.6 | C32: =LN(B32/B31) -> -0.022276311 | D32: =C32^2 -> 0.00049623403 | F32: =SQRT(AVERAGE(D7:D31)) -> 0.030648546
A33: 13990818 | B33: 6975.4 | C33: =LN(B33/B32) -> -0.030524005 | D33: =C33^2 -> 0.00093171485 | F33: =SQRT(AVERAGE(D8:D32)) -> 0.029687902
A34: 13990819 | B34: 6769.1 | C34: =LN(B34/B33) -> -0.030021535 | D34: =C34^2 -> 0.00090129257 | F34: =SQRT(AVERAGE(D9:D33)) -> 0.029797516
A35: 13990820 | B35: 6707.4 | C35: =LN(B35/B34) -> -0.0091567441 | D35: =C35^2 -> 8.3845963e-05 | F35: =SQRT(AVERAGE(D10:D34)) -> 0.03038663
A36: 13990821 | B36: 6729.8 | C36: =LN(B36/B35) -> 0.003334031 | D36: =C36^2 -> 1.1115763e-05 | F36: =SQRT(AVERAGE(D11:D35)) -> 0.02924265
A37: 13990824 | B37: 6975.6 | C37: =LN(B37/B36) -> 0.03587292 | D37: =C37^2 -> 0.0012868664 | F37: =SQRT(AVERAGE(D12:D36)) -> 0.029188208
A38: 13990825 | B38: 7146.4 | C38: =LN(B38/B37) -> 0.024190388 | D38: =C38^2 -> 0.00058517487 | F38: =SQRT(AVERAGE(D13:D37)) -> 0.030051264
A39: 13990826 | B39: 7348 | C39: =LN(B39/B38) -> 0.027819434 | D39: =C39^2 -> 0.00077392091 | F39: =SQRT(AVERAGE(D14:D38)) -> 0.029291665
... A52: 13990915 | B52: 9208.2 | C52: =LN(B52/B51) -> 0.0055211758 | D52: =C52^2 -> 3.0483382e-05 | F52: =SQRT(AVERAGE(D27:D51)) -> 0.024416443
A53: 13990916 | B53: 9183.8 | C53: =LN(B53/B52) -> -0.0026533291 | D53: =C53^2 -> 7.0401553e-06 | F53: =SQRT(AVERAGE(D28:D52)) -> 0.024091153 | H53: =SQRT(AVERAGE(D3:D52)) -> 0.027380174
A54: 13990917 | B54: 9294.2 | C54: =LN(B54/B53) -> 0.011949487 | D54: =C54^2 -> 0.00014279025 | F54: =SQRT(AVERAGE(D29:D53)) -> 0.023274913 | H54: =SQRT(AVERAGE(D4:D53)) -> 0.027245527
A55: 13990918 | B55: 9299.6 | C55: =LN(B55/B54) -> 0.00058083879 | D55: =C55^2 -> 3.373737e-07 | F55: =SQRT(AVERAGE(D30:D54)) -> 0.022901224 | H55: =SQRT(AVERAGE(D5:D54)) -> 0.027228679
A56: 13990919 | B56: 9173.8 | C56: =LN(B56/B55) -> -0.013619793 | D56: =C56^2 -> 0.00018549877 | F56: =SQRT(AVERAGE(D31:D55)) -> 0.022843132 | H56: =SQRT(AVERAGE(D6:D55)) -> 0.027226084
A57: 13990922 | B57: 9235.5 | C57: =LN(B57/B56) -> 0.0067031588 | D57: =C57^2 -> 4.4932338e-05 | F57: =SQRT(AVERAGE(D32:D56)) -> 0.022959263 | H57: =SQRT(AVERAGE(D7:D56)) -> 0.02707823
A58: 13990923 | B58: 9108.9 | C58: =LN(B58/B57) -> -0.013802796 | D58: =C58^2 -> 0.00019051719 | F58: =SQRT(AVERAGE(D33:D57)) -> 0.022562706 | H58: =SQRT(AVERAGE(D8:D57)) -> 0.026367094
A59: 13990924 | B59: 9183.5 | C59: =LN(B59/B58) -> 0.008156438 | D59: =C59^2 -> 6.6527481e-05 | F59: =SQRT(AVERAGE(D34:D58)) -> 0.02189584 | H59: =SQRT(AVERAGE(D9:D58)) -> 0.02614689
A60: 13990925 | B60: 8818.1 | C60: =LN(B60/B59) -> -0.040601968 | D60: =C60^2 -> 0.0016485198 | F60: =SQRT(AVERAGE(D35:D59)) -> 0.021119593 | H60: =SQRT(AVERAGE(D10:D59)) -> 0.026166625
A61: 13990926 | B61: 8562.9 | C61: =LN(B61/B60) -> -0.029367509 | D61: =C61^2 -> 0.00086245061 | F61: =SQRT(AVERAGE(D36:D60)) -> 0.022552697 | H61: =SQRT(AVERAGE(D11:D60)) -> 0.026112801
A62: 13990929 | B62: 8585.9 | C62: =LN(B62/B61) -> 0.002682405 | D62: =C62^2 -> 7.1952968e-06 | F62: =SQRT(AVERAGE(D37:D61)) -> 0.02329544 | H62: =SQRT(AVERAGE(D12:D61)) -> 0.026406713
A63: 13990930 | B63: 8348.6 | C63: =LN(B63/B62) -> -0.028027463 | D63: =C63^2 -> 0.00078553867 | F63: =SQRT(AVERAGE(D38:D62)) -> 0.02216959 | H63: =SQRT(AVERAGE(D13:D62)) -> 0.026406147
A64: 13991001 | B64: 8319.1 | C64: =LN(B64/B63) -> -0.0035397842 | D64: =C64^2 -> 1.2530072e-05 | F64: =SQRT(AVERAGE(D39:D63)) -> 0.022349614 | H64: =SQRT(AVERAGE(D14:D63)) -> 0.026052897
...

Sheet EMA
A1: تاریخ | B1: شاخص قیمت | C1: بازدهی | D1: مجذور بازدهی | E1: میانگین متحرک 25 | F1: ـ | G1: λ | H1: میانگین متحرک نمایی | I1: STD
A2: 13990631 | B2: 8809 | F2: τ | G2: 0.94
A3: 13990701 | B3: 8640.1 | C3: =LN(B3/B2) -> -0.019359769 | D3: =C3^2 -> 0.00037480067 | F3: 25 | G3: =($G$2^(F3-1))*D3 -> 8.4892406e-05
A4: 13990702 | B4: 8759.6 | C4: =LN(B4/B3) -> 0.013736085 | D4: =C4^2 -> 0.00018868003 | F4: 24 | G4: =($G$2^(F4-1))*D4 -> 4.5463888e-05
A5: 13990705 | B5: 8735.8 | C5: =LN(B5/B4) -> -0.0027207168 | D5: =C5^2 -> 7.4023001e-06 | F5: 23 | G5: =($G$2^(F5-1))*D5 -> 1.8974899e-06
A6: 13990706 | B6: 8526.7 | C6: =LN(B6/B5) -> -0.024227108 | D6: =C6^2 -> 0.00058695277 | F6: 22 | G6: =($G$2^(F6-1))*D6 -> 0.00016006194
A7: 13990707 | B7: 8158.8 | C7: =LN(B7/B6) -> -0.044105317 | D7: =C7^2 -> 0.001945279 | F7: 21 | G7: =($G$2^(F7-1))*D7 -> 0.00056433759
A8: 13990708 | B8: 7935.7 | C8: =LN(B8/B7) -> -0.027725532 | D8: =C8^2 -> 0.00076870515 | F8: 20 | G8: =($G$2^(F8-1))*D8 -> 0.0002372406
A9: 13990709 | B9: 7966.4 | C9: =LN(B9/B8) -> 0.0038611301 | D9: =C9^2 -> 1.4908325e-05 | F9: 19 | G9: =($G$2^(F9-1))*D9 -> 4.8947467e-06
A10: 13990712 | B10: 8310.6 | C10: =LN(B10/B9) -> 0.042299112 | D10: =C10^2 -> 0.0017892148 | F10: 18 | G10: =($G$2^(F10-1))*D10 -> 0.00062493666
A11: 13990713 | B11: 8390.1 | C11: =LN(B11/B10) -> 0.0095206309 | D11: =C11^2 -> 9.0642413e-05 | F11: 17 | G11: =($G$2^(F11-1))*D11 -> 3.368039e-05
A12: 13990714 | B12: 8365.4 | C12: =LN(B12/B11) -> -0.0029482878 | D12: =C12^2 -> 8.6924008e-06 | F12: 16 | G12: =($G$2^(F12-1))*D12 -> 3.4360347e-06
A13: 13990715 | B13: 8718.8 | C13: =LN(B13/B12) -> 0.041377462 | D13: =C13^2 -> 0.0017120944 | F13: 15 | G13: =($G$2^(F13-1))*D13 -> 0.00071997539
A14: 13990716 | B14: 9037.1 | C14: =LN(B14/B13) -> 0.035856713 | D14: =C14^2 -> 0.0012857038 | F14: 14 | G14: =($G$2^(F14-1))*D14 -> 0.00057517902
... A27: 13990807 | B27: 7307.3 | C27: =LN(B27/B26) -> -0.020614539 | D27: =C27^2 -> 0.00042495923 | F27: 1 | G27: =($G$2^(F27-1))*D27 -> 0.00042495923
A28: 13990810 | B28: 7538.9 | C28: =LN(B28/B27) -> 0.031202434 | D28: =C28^2 -> 0.00097359191 | E28: =SQRT(AVERAGE(D3:D27)) -> 0.030314423 | H28: =SUM(G3:G27)*(1-G2) -> 0.00078442206 | I28: =SQRT(H28) -> 0.028007536
A29: 13990811 | B29: 7360.4 | C29: =LN(B29/B28) -> -0.023962004 | D29: =C29^2 -> 0.00057417762 | E29: =SQRT(AVERAGE(D4:D28)) -> 0.030706936 | H29: =($G$2*H28)+((1-$G$2)*D28) -> 0.00079577225 | I29: =SQRT(H29) -> 0.028209436
A30: 13990812 | B30: 7300.5 | C30: =LN(B30/B29) -> -0.0081714401 | D30: =C30^2 -> 6.6772434e-05 | E30: =SQRT(AVERAGE(D5:D29)) -> 0.030956999 | H30: =($G$2*H29)+((1-$G$2)*D29) -> 0.00078247658 | I30: =SQRT(H30) -> 0.027972783
A31: 13990814 | B31: 7353.6 | C31: =LN(B31/B30) -> 0.0072471503 | D31: =C31^2 -> 5.2521187e-05 | E31: =SQRT(AVERAGE(D6:D30)) -> 0.030995332 | H31: =($G$2*H30)+((1-$G$2)*D30) -> 0.00073953433 | I31: =SQRT(H31) -> 0.02719438
A32: 13990817 | B32: 7191.6 | C32: =LN(B32/B31) -> -0.022276311 | D32: =C32^2 -> 0.00049623403 | E32: =SQRT(AVERAGE(D7:D31)) -> 0.030648546 | H32: =($G$2*H31)+((1-$G$2)*D31) -> 0.00069831354 | I32: =SQRT(H32) -> 0.026425623
A33: 13990818 | B33: 6975.4 | C33: =LN(B33/B32) -> -0.030524005 | D33: =C33^2 -> 0.00093171485 | E33: =SQRT(AVERAGE(D8:D32)) -> 0.029687902 | H33: =($G$2*H32)+((1-$G$2)*D32) -> 0.00068618877 | I33: =SQRT(H33) -> 0.026195205
A34: 13990819 | B34: 6769.1 | C34: =LN(B34/B33) -> -0.030021535 | D34: =C34^2 -> 0.00090129257 | E34: =SQRT(AVERAGE(D9:D33)) -> 0.029797516 | H34: =($G$2*H33)+((1-$G$2)*D33) -> 0.00070092033 | I34: =SQRT(H34) -> 0.0264749
A35: 13990820 | B35: 6707.4 | C35: =LN(B35/B34) -> -0.0091567441 | D35: =C35^2 -> 8.3845963e-05 | E35: =SQRT(AVERAGE(D10:D34)) -> 0.03038663 | H35: =($G$2*H34)+((1-$G$2)*D34) -> 0.00071294267 | I35: =SQRT(H35) -> 0.026700986
A36: 13990821 | B36: 6729.8 | C36: =LN(B36/B35) -> 0.003334031 | D36: =C36^2 -> 1.1115763e-05 | E36: =SQRT(AVERAGE(D11:D35)) -> 0.02924265 | H36: =($G$2*H35)+((1-$G$2)*D35) -> 0.00067519687 | I36: =SQRT(H36) -> 0.025984551
A37: 13990824 | B37: 6975.6 | C37: =LN(B37/B36) -> 0.03587292 | D37: =C37^2 -> 0.0012868664 | E37: =SQRT(AVERAGE(D12:D36)) -> 0.029188208 | H37: =($G$2*H36)+((1-$G$2)*D36) -> 0.000635352 | I37: =SQRT(H37) -> 0.02520619
A38: 13990825 | B38: 7146.4 | C38: =LN(B38/B37) -> 0.024190388 | D38: =C38^2 -> 0.00058517487 | E38: =SQRT(AVERAGE(D13:D37)) -> 0.030051264 | H38: =($G$2*H37)+((1-$G$2)*D37) -> 0.00067444286 | I38: =SQRT(H38) -> 0.025970038
A39: 13990826 | B39: 7348 | C39: =LN(B39/B38) -> 0.027819434 | D39: =C39^2 -> 0.00077392091 | E39: =SQRT(AVERAGE(D14:D38)) -> 0.029291665 | H39: =($G$2*H38)+((1-$G$2)*D38) -> 0.00066908678 | I39: =SQRT(H39) -> 0.025866712
A40: 13990827 | B40: 7599.1 | C40: =LN(B40/B39) -> 0.033601652 | D40: =C40^2 -> 0.001129071 | E40: =SQRT(AVERAGE(D15:D39)) -> 0.028940117 | H40: =($G$2*H39)+((1-$G$2)*D39) -> 0.00067537683 | I40: =SQRT(H40) -> 0.025988013
... A127: 14000110 | B127: 7447.9 | C127: =LN(B127/B126) -> -0.0057968849 | D127: =C127^2 -> 3.3603874e-05 | E127: =SQRT(AVERAGE(D102:D126)) -> 0.013414582 | H127: =($G$2*H126)+((1-$G$2)*D126) -> 0.00033333863 | I127: =SQRT(H127) -> 0.018257564

Sheet VaR02
A1: تاریخ | B1: شاخص قیمت | C1: بازدهی | D1: مجذور بازدهی | E1: میانگین متحرک 25 | F1: ـ | G1: λ | H1: میانگین متحرک نمایی | I1: STD | J1: ارزش بازار | K1: VaR 25 | L1: VaR Ex
A2: 13990631 | B2: 8809 | F2: τ | G2: 0.94
A3: 13990701 | B3: 8640.1 | C3: =LN(B3/B2) -> -0.019359769 | D3: =C3^2 -> 0.00037480067 | F3: 25 | G3: =($G$2^(F3-1))*D3 -> 8.4892406e-05
A4: 13990702 | B4: 8759.6 | C4: =LN(B4/B3) -> 0.013736085 | D4: =C4^2 -> 0.00018868003 | F4: 24 | G4: =($G$2^(F4-1))*D4 -> 4.5463888e-05
A5: 13990705 | B5: 8735.8 | C5: =LN(B5/B4) -> -0.0027207168 | D5: =C5^2 -> 7.4023001e-06 | F5: 23 | G5: =($G$2^(F5-1))*D5 -> 1.8974899e-06
A6: 13990706 | B6: 8526.7 | C6: =LN(B6/B5) -> -0.024227108 | D6: =C6^2 -> 0.00058695277 | F6: 22 | G6: =($G$2^(F6-1))*D6 -> 0.00016006194
A7: 13990707 | B7: 8158.8 | C7: =LN(B7/B6) -> -0.044105317 | D7: =C7^2 -> 0.001945279 | F7: 21 | G7: =($G$2^(F7-1))*D7 -> 0.00056433759
A8: 13990708 | B8: 7935.7 | C8: =LN(B8/B7) -> -0.027725532 | D8: =C8^2 -> 0.00076870515 | F8: 20 | G8: =($G$2^(F8-1))*D8 -> 0.0002372406
A9: 13990709 | B9: 7966.4 | C9: =LN(B9/B8) -> 0.0038611301 | D9: =C9^2 -> 1.4908325e-05 | F9: 19 | G9: =($G$2^(F9-1))*D9 -> 4.8947467e-06
A10: 13990712 | B10: 8310.6 | C10: =LN(B10/B9) -> 0.042299112 | D10: =C10^2 -> 0.0017892148 | F10: 18 | G10: =($G$2^(F10-1))*D10 -> 0.00062493666
A11: 13990713 | B11: 8390.1 | C11: =LN(B11/B10) -> 0.0095206309 | D11: =C11^2 -> 9.0642413e-05 | F11: 17 | G11: =($G$2^(F11-1))*D11 -> 3.368039e-05
A12: 13990714 | B12: 8365.4 | C12: =LN(B12/B11) -> -0.0029482878 | D12: =C12^2 -> 8.6924008e-06 | F12: 16 | G12: =($G$2^(F12-1))*D12 -> 3.4360347e-06
A13: 13990715 | B13: 8718.8 | C13: =LN(B13/B12) -> 0.041377462 | D13: =C13^2 -> 0.0017120944 | F13: 15 | G13: =($G$2^(F13-1))*D13 -> 0.00071997539
A14: 13990716 | B14: 9037.1 | C14: =LN(B14/B13) -> 0.035856713 | D14: =C14^2 -> 0.0012857038 | F14: 14 | G14: =($G$2^(F14-1))*D14 -> 0.00057517902
... A26: 13990806 | B26: 7459.5 | C26: =LN(B26/B25) -> -0.026393039 | D26: =C26^2 -> 0.00069659251 | F26: 2 | G26: =($G$2^(F26-1))*D26 -> 0.00065479696
A27: 13990807 | B27: 7307.3 | C27: =LN(B27/B26) -> -0.020614539 | D27: =C27^2 -> 0.00042495923 | F27: 1 | G27: =($G$2^(F27-1))*D27 -> 0.00042495923 | J27: 100000000
A28: 13990810 | B28: 7538.9 | C28: =LN(B28/B27) -> 0.031202434 | D28: =C28^2 -> 0.00097359191 | E28: =SQRT(AVERAGE(D3:D27)) -> 0.030314423 | H28: =SUM(G3:G27)*(1-G2) -> 0.00078442206 | I28: =SQRT(H28) -> 0.028007536 | J28: =J27*(1+C27) -> 97938546 | K28: =_xlfn.NORM.S.INV(0.99)*E28*J28 -> 6906811.8 | L28: =_xlfn.NORM.S.INV(0.99)*I28*J28 -> 6381212.6
A29: 13990811 | B29: 7360.4 | C29: =LN(B29/B28) -> -0.023962004 | D29: =C29^2 -> 0.00057417762 | E29: =SQRT(AVERAGE(D4:D28)) -> 0.030706936 | H29: =($G$2*H28)+((1-$G$2)*D28) -> 0.00079577225 | I29: =SQRT(H29) -> 0.028209436 | J29: =J28*(1+C28) -> 1.0099447e+08 | K29: =_xlfn.NORM.S.INV(0.99)*E29*J29 -> 7214541.3 | L29: =_xlfn.NORM.S.INV(0.99)*I29*J29 -> 6627757.9
A30: 13990812 | B30: 7300.5 | C30: =LN(B30/B29) -> -0.0081714401 | D30: =C30^2 -> 6.6772434e-05 | E30: =SQRT(AVERAGE(D5:D29)) -> 0.030956999 | H30: =($G$2*H29)+((1-$G$2)*D29) -> 0.00078247658 | I30: =SQRT(H30) -> 0.027972783 | J30: =J29*(1+C29) -> 98574437 | K30: =_xlfn.NORM.S.INV(0.99)*E30*J30 -> 7099010.6 | L30: =_xlfn.NORM.S.INV(0.99)*I30*J30 -> 6414674.7
A31: 13990814 | B31: 7353.6 | C31: =LN(B31/B30) -> 0.0072471503 | D31: =C31^2 -> 5.2521187e-05 | E31: =SQRT(AVERAGE(D6:D30)) -> 0.030995332 | H31: =($G$2*H30)+((1-$G$2)*D30) -> 0.00073953433 | I31: =SQRT(H31) -> 0.02719438 | J31: =J30*(1+C30) -> 97768942 | K31: =_xlfn.NORM.S.INV(0.99)*E31*J31 -> 7049720 | L31: =_xlfn.NORM.S.INV(0.99)*I31*J31 -> 6185214.2
A32: 13990817 | B32: 7191.6 | C32: =LN(B32/B31) -> -0.022276311 | D32: =C32^2 -> 0.00049623403 | E32: =SQRT(AVERAGE(D7:D31)) -> 0.030648546 | H32: =($G$2*H31)+((1-$G$2)*D31) -> 0.00069831354 | I32: =SQRT(H32) -> 0.026425623 | J32: =J31*(1+C31) -> 98477488 | K32: =_xlfn.NORM.S.INV(0.99)*E32*J32 -> 7021364.1 | L32: =_xlfn.NORM.S.INV(0.99)*I32*J32 -> 6053922.4
A33: 13990818 | B33: 6975.4 | C33: =LN(B33/B32) -> -0.030524005 | D33: =C33^2 -> 0.00093171485 | E33: =SQRT(AVERAGE(D8:D32)) -> 0.029687902 | H33: =($G$2*H32)+((1-$G$2)*D32) -> 0.00068618877 | I33: =SQRT(H33) -> 0.026195205 | J33: =J32*(1+C32) -> 96283773 | K33: =_xlfn.NORM.S.INV(0.99)*E33*J33 -> 6649779.9 | L33: =_xlfn.NORM.S.INV(0.99)*I33*J33 -> 5867452.2
A34: 13990819 | B34: 6769.1 | C34: =LN(B34/B33) -> -0.030021535 | D34: =C34^2 -> 0.00090129257 | E34: =SQRT(AVERAGE(D9:D33)) -> 0.029797516 | H34: =($G$2*H33)+((1-$G$2)*D33) -> 0.00070092033 | I34: =SQRT(H34) -> 0.0264749 | J34: =J33*(1+C33) -> 93344807 | K34: =_xlfn.NORM.S.INV(0.99)*E34*J34 -> 6470604.8 | L34: =_xlfn.NORM.S.INV(0.99)*I34*J34 -> 5749090.6
A35: 13990820 | B35: 6707.4 | C35: =LN(B35/B34) -> -0.0091567441 | D35: =C35^2 -> 8.3845963e-05 | E35: =SQRT(AVERAGE(D10:D34)) -> 0.03038663 | H35: =($G$2*H34)+((1-$G$2)*D34) -> 0.00071294267 | I35: =SQRT(H35) -> 0.026700986 | J35: =J34*(1+C34) -> 90542453 | K35: =_xlfn.NORM.S.INV(0.99)*E35*J35 -> 6400434.5 | L35: =_xlfn.NORM.S.INV(0.99)*I35*J35 -> 5624115.3
A36: 13990821 | B36: 6729.8 | C36: =LN(B36/B35) -> 0.003334031 | D36: =C36^2 -> 1.1115763e-05 | E36: =SQRT(AVERAGE(D11:D35)) -> 0.02924265 | H36: =($G$2*H35)+((1-$G$2)*D35) -> 0.00067519687 | I36: =SQRT(H36) -> 0.025984551 | J36: =J35*(1+C35) -> 89713378 | K36: =_xlfn.NORM.S.INV(0.99)*E36*J36 -> 6103073.4 | L36: =_xlfn.NORM.S.INV(0.99)*I36*J36 -> 5423093.3
A37: 13990824 | B37: 6975.6 | C37: =LN(B37/B36) -> 0.03587292 | D37: =C37^2 -> 0.0012868664 | E37: =SQRT(AVERAGE(D12:D36)) -> 0.029188208 | H37: =($G$2*H36)+((1-$G$2)*D36) -> 0.000635352 | I37: =SQRT(H37) -> 0.02520619 | J37: =J36*(1+C36) -> 90012486 | K37: =_xlfn.NORM.S.INV(0.99)*E37*J37 -> 6112021.1 | L37: =_xlfn.NORM.S.INV(0.99)*I37*J37 -> 5278185.1
A38: 13990825 | B38: 7146.4 | C38: =LN(B38/B37) -> 0.024190388 | D38: =C38^2 -> 0.00058517487 | E38: =SQRT(AVERAGE(D13:D37)) -> 0.030051264 | H38: =($G$2*H37)+((1-$G$2)*D37) -> 0.00067444286 | I38: =SQRT(H38) -> 0.025970038 | J38: =J37*(1+C37) -> 93241496 | K38: =_xlfn.NORM.S.INV(0.99)*E38*J38 -> 6518484.4 | L38: =_xlfn.NORM.S.INV(0.99)*I38*J38 -> 5633216.9
A39: 13990826 | B39: 7348 | C39: =LN(B39/B38) -> 0.027819434 | D39: =C39^2 -> 0.00077392091 | E39: =SQRT(AVERAGE(D14:D38)) -> 0.029291665 | H39: =($G$2*H38)+((1-$G$2)*D38) -> 0.00066908678 | I39: =SQRT(H39) -> 0.025866712 | J39: =J38*(1+C38) -> 95497044 | K39: =_xlfn.NORM.S.INV(0.99)*E39*J39 -> 6507417.2 | L39: =_xlfn.NORM.S.INV(0.99)*I39*J39 -> 5746531.8
A40: 13990827 | B40: 7599.1 | C40: =LN(B40/B39) -> 0.033601652 | D40: =C40^2 -> 0.001129071 | E40: =SQRT(AVERAGE(D15:D39)) -> 0.028940117 | H40: =($G$2*H39)+((1-$G$2)*D39) -> 0.00067537683 | I40: =SQRT(H40) -> 0.025988013 | J40: =J39*(1+C39) -> 98153718 | K40: =_xlfn.NORM.S.INV(0.99)*E40*J40 -> 6608177.4 | L40: =_xlfn.NORM.S.INV(0.99)*I40*J40 -> 5934095
... A1187: 14040631 | B1187: 14857.7 | C1187: =LN(B1187/B1186) -> 0.022853508 | D1187: =C1187^2 -> 0.00052228285 | E1187: =SQRT(AVERAGE(D1162:D1186)) -> 0.015456745 | H1187: =($G$2*H1186)+((1-$G$2)*D1186) -> 0.00028160357 | I1187: =SQRT(H1187) -> 0.016781048 | J1187: =J1186*(1+C1186) -> 1.6642048e+08 | K1187: =_xlfn.NORM.S.INV(0.99)*E1187*J1187 -> 5984108.6 | L1187: =_xlfn.NORM.S.INV(0.99)*I1187*J1187 -> 6496815

Sheet GARCH
A1: تاریخ | B1: شاخص قیمت | C1: بازدهی | D1: واریانس شرطی | E1: درستنمایی
A2: 13990631 | B2: 8809 | I2: مقادیر ابتدایی | K2: بدون استفاده از واریانس بلندمدت
A3: 13990701 | B3: 8640.1 | C3: =LN(B3/B2) -> -0.019359769 | D3: =_xlfn.VAR.S(C3:C1187) -> 0.0002846571 | E3: =(-0.5*LN(2*PI())) - (0.5*LN(D3)) - (0.5*((C3^2)/D3)) -> 2.504837 | I3: α₀ | J3: 0.05 | K3: α | L3: 0.057513275
A4: 13990702 | B4: 8759.6 | C4: =LN(B4/B3) -> 0.013736085 | D4: =$L$5+($L$3*(C3^2))+($L$4*D3) -> 0.00028953135 | E4: =(-0.5*LN(2*PI())) - (0.5*LN(D4)) - (0.5*((C4^2)/D4)) -> 2.828848 | I4: β₀ | J4: 0.9 | K4: β | L4: 0.92401837
A5: 13990705 | B5: 8735.8 | C5: =LN(B5/B4) -> -0.0027207168 | D5: =$L$5+($L$3*(C4^2))+($L$4*D4) -> 0.00028333085 | E5: =(-0.5*LN(2*PI())) - (0.5*LN(D5)) - (0.5*((C5^2)/D5)) -> 3.1524461 | I5: ω₀ | J5: =D3*(1-J3-J4) -> 1.4232855e-05 | K5: ω | L5: 4.9469546e-06
A6: 13990706 | B6: 8526.7 | C6: =LN(B6/B5) -> -0.024227108 | D6: =$L$5+($L$3*(C5^2))+($L$4*D5) -> 0.00026717559 | E6: =(-0.5*LN(2*PI())) - (0.5*LN(D6)) - (0.5*((C6^2)/D6)) -> 2.0964236 | I6: α₀ + β₀ | J6: =J3+J4 -> 0.95 | K6: α + β | L6: =J3+J4 -> 0.95
A7: 13990707 | B7: 8158.8 | C7: =LN(B7/B6) -> -0.044105317 | D7: =$L$5+($L$3*(C6^2))+($L$4*D6) -> 0.00028557969 | E7: =(-0.5*LN(2*PI())) - (0.5*LN(D7)) - (0.5*((C7^2)/D7)) -> -0.24428658 | I7: MLE | J7: 3220.1035 | K7: MLE | L7: =SUM(E3:E1187) -> 3229.2013
A8: 13990708 | B8: 7935.7 | C8: =LN(B8/B7) -> -0.027725532 | D8: =$L$5+($L$3*(C7^2))+($L$4*D7) -> 0.0003807072 | E8: =(-0.5*LN(2*PI())) - (0.5*LN(D8)) - (0.5*((C8^2)/D8)) -> 2.0082262
A9: 13990709 | B9: 7966.4 | C9: =LN(B9/B8) -> 0.0038611301 | D9: =$L$5+($L$3*(C8^2))+($L$4*D8) -> 0.00040093815 | E9: =(-0.5*LN(2*PI())) - (0.5*LN(D9)) - (0.5*((C9^2)/D9)) -> 2.9733214
A10: 13990712 | B10: 8310.6 | C10: =LN(B10/B9) -> 0.042299112 | D10: =$L$5+($L$3*(C9^2))+($L$4*D9) -> 0.00037627859 | E10: =(-0.5*LN(2*PI())) - (0.5*LN(D10)) - (0.5*((C10^2)/D10)) -> 0.64613839
A11: 13990713 | B11: 8390.1 | C11: =LN(B11/B10) -> 0.0095206309 | D11: =$L$5+($L$3*(C10^2))+($L$4*D10) -> 0.00045553889 | E11: =(-0.5*LN(2*PI())) - (0.5*LN(D11)) - (0.5*((C11^2)/D11)) -> 2.828587
A12: 13990714 | B12: 8365.4 | C12: =LN(B12/B11) -> -0.0029482878 | D12: =$L$5+($L$3*(C11^2))+($L$4*D11) -> 0.0004310864 | E12: =(-0.5*LN(2*PI())) - (0.5*LN(D12)) - (0.5*((C12^2)/D12)) -> 2.9455805
A13: 13990715 | B13: 8718.8 | C13: =LN(B13/B12) -> 0.041377462 | D13: =$L$5+($L$3*(C12^2))+($L$4*D12) -> 0.00040377863 | E13: =(-0.5*LN(2*PI())) - (0.5*LN(D13)) - (0.5*((C13^2)/D13)) -> 0.86829299
A14: 13990716 | B14: 9037.1 | C14: =LN(B14/B13) -> 0.035856713 | D14: =$L$5+($L$3*(C13^2))+($L$4*D13) -> 0.00047651398 | E14: =(-0.5*LN(2*PI())) - (0.5*LN(D14)) - (0.5*((C14^2)/D14)) -> 1.5564957
A15: 13990719 | B15: 9242.3 | C15: =LN(B15/B14) -> 0.022452446 | D15: =$L$5+($L$3*(C14^2))+($L$4*D14) -> 0.00051919967 | E15: =(-0.5*LN(2*PI())) - (0.5*LN(D15)) - (0.5*((C15^2)/D15)) -> 2.3772019
A16: 13990720 | B16: 9677.5 | C16: =LN(B16/B15) -> 0.046012831 | D16: =$L$5+($L$3*(C15^2))+($L$4*D15) -> 0.00051369013 | E16: =(-0.5*LN(2*PI())) - (0.5*LN(D16)) - (0.5*((C16^2)/D16)) -> 0.80725007
A17: 13990721 | B17: 9450.3 | C17: =LN(B17/B16) -> -0.023757116 | D17: =$L$5+($L$3*(C16^2))+($L$4*D16) -> 0.00060137206 | E17: =(-0.5*LN(2*PI())) - (0.5*LN(D17)) - (0.5*((C17^2)/D17)) -> 2.3199491
A18: 13990722 | B18: 9303.1 | C18: =LN(B18/B17) -> -0.015698809 | D18: =$L$5+($L$3*(C17^2))+($L$4*D17) -> 0.00059308631 | E18: =(-0.5*LN(2*PI())) - (0.5*LN(D18)) - (0.5*((C18^2)/D18)) -> 2.5883755
A19: 13990723 | B19: 9101.3 | C19: =LN(B19/B18) -> -0.021930417 | D19: =$L$5+($L$3*(C18^2))+($L$4*D18) -> 0.0005671439 | E19: =(-0.5*LN(2*PI())) - (0.5*LN(D19)) - (0.5*((C19^2)/D19)) -> 2.3945056
... A1187: 14040631 | B1187: 14857.7 | C1187: =LN(B1187/B1186) -> 0.022853508 | D1187: =$L$5+($L$3*(C1186^2))+($L$4*D1186) -> 0.00027965421 | E1187: =(-0.5*LN(2*PI())) - (0.5*LN(D1187)) - (0.5*((C1187^2)/D1187)) -> 2.2382387

Sheet Historical
A1: تاریخ | B1: شاخص قیمت بانک | C1: شاخص قیمت محصولات شیمیایی | D1: ـ | E1: بازدهی بانک | F1: بازدهی محصولات شیمیایی | G1: میانگین | H1: ارزش پرتفوی | I1: تغییر در ارزش | O1: ارزش فعلی | P1: وزن
A2: 14030531 | B2: 7856.4 | C2: 172216 | L2: ردیف | O2: 1000000000 | P2: 0.5
A3: 14030603 | B3: 7940 | C3: 173305 | E3: =LN(B3/B2) -> 0.010584789 | F3: =LN(C3/C2) -> 0.0063035451 | G3: =($P$2*E3)+((1-$P$2)*F3) -> 0.0084441671 | H3: =$O$2*EXP(G3) -> 1.0084799e+09 | I3: =H3-$O$2 -> 8479919.6 | L3: 1 | M3: -49574812
A4: 14030605 | B4: 7967.6 | C4: 174494 | E4: =LN(B4/B3) -> 0.003470043 | F4: =LN(C4/C3) -> 0.0068373091 | G4: =($P$2*E4)+((1-$P$2)*F4) -> 0.005153676 | H4: =$O$2*EXP(G4) -> 1.005167e+09 | I4: =H4-$O$2 -> 5166979.1 | L4: 2 | M4: -33292444
A5: 14030606 | B5: 8000.3 | C5: 174926 | E5: =LN(B5/B4) -> 0.0040957228 | F5: =LN(C5/C4) -> 0.0024726703 | G5: =($P$2*E5)+((1-$P$2)*F5) -> 0.0032841965 | H5: =$O$2*EXP(G5) -> 1.0032896e+09 | I5: =H5-$O$2 -> 3289595.4 | L5: 3 | M5: -28496905
A6: 14030607 | B6: 8053.2 | C6: 175522 | E6: =LN(B6/B5) -> 0.006590487 | F6: =LN(C6/C5) -> 0.0034013638 | G6: =($P$2*E6)+((1-$P$2)*F6) -> 0.0049959254 | H6: =$O$2*EXP(G6) -> 1.0050084e+09 | I6: =H6-$O$2 -> 5008425.9 | L6: 4 | M6: -27954573 | N6: VaR 99%
A7: 14030610 | B7: 8149.7 | C7: 177346 | E7: =LN(B7/B6) -> 0.011911589 | F7: =LN(C7/C6) -> 0.010338236 | G7: =($P$2*E7)+((1-$P$2)*F7) -> 0.011124912 | H7: =$O$2*EXP(G7) -> 1.011187e+09 | I7: =H7-$O$2 -> 11187024 | L7: 5 | M7: -24870986
A8: 14030611 | B8: 8242.6 | C8: 178527 | E8: =LN(B8/B7) -> 0.011334711 | F8: =LN(C8/C7) -> 0.0066372236 | G8: =($P$2*E8)+((1-$P$2)*F8) -> 0.0089859675 | H8: =$O$2*EXP(G8) -> 1.0090265e+09 | I8: =H8-$O$2 -> 9026462.5 | L8: 6 | M8: -23520517
A9: 14030613 | B9: 8262.6 | C9: 179367 | E9: =LN(B9/B8) -> 0.0024234798 | F9: =LN(C9/C8) -> 0.0046941359 | G9: =($P$2*E9)+((1-$P$2)*F9) -> 0.0035588079 | H9: =$O$2*EXP(G9) -> 1.0035651e+09 | I9: =H9-$O$2 -> 3565148 | L9: 7 | M9: -22762462
A10: 14030617 | B10: 8217.8 | C10: 179664 | E10: =LN(B10/B9) -> -0.0054367746 | F10: =LN(C10/C9) -> 0.0016544536 | G10: =($P$2*E10)+((1-$P$2)*F10) -> -0.0018911605 | H10: =$O$2*EXP(G10) -> 9.9811063e+08 | I10: =H10-$O$2 -> -1889373.4 | L10: 8 | M10: -22630918
A11: 14030618 | B11: 8181.7 | C11: 178909 | E11: =LN(B11/B10) -> -0.0044025804 | F11: =LN(C11/C10) -> -0.0042111431 | G11: =($P$2*E11)+((1-$P$2)*F11) -> -0.0043068618 | H11: =$O$2*EXP(G11) -> 9.957024e+08 | I11: =H11-$O$2 -> -4297600.5 | L11: 9 | M11: -21815670
A12: 14030619 | B12: 8258.8 | C12: 178926 | E12: =LN(B12/B11) -> 0.0093793455 | F12: =LN(C12/C11) -> 9.5015859e-05 | G12: =($P$2*E12)+((1-$P$2)*F12) -> 0.0047371807 | H12: =$O$2*EXP(G12) -> 1.0047484e+09 | I12: =H12-$O$2 -> 4748418.9 | L12: 10 | M12: -21472433
A13: 14030620 | B13: 8285.1 | C13: 177629 | E13: =LN(B13/B12) -> 0.0031794223 | F13: =LN(C13/C12) -> -0.007275207 | G13: =($P$2*E13)+((1-$P$2)*F13) -> -0.0020478924 | H13: =$O$2*EXP(G13) -> 9.979542e+08 | I13: =H13-$O$2 -> -2045796.9 | L13: 11 | M13: -21377683
A14: 14030621 | B14: 8309.4 | C14: 176273 | E14: =LN(B14/B13) -> 0.0029286833 | F14: =LN(C14/C13) -> -0.0076631759 | G14: =($P$2*E14)+((1-$P$2)*F14) -> -0.0023672463 | H14: =$O$2*EXP(G14) -> 9.9763555e+08 | I14: =H14-$O$2 -> -2364446.6 | L14: 12 | M14: -21188920
A15: 14030624 | B15: 8272.7 | C15: 175435 | E15: =LN(B15/B14) -> -0.0044264671 | F15: =LN(C15/C14) -> -0.0047653257 | G15: =($P$2*E15)+((1-$P$2)*F15) -> -0.0045958964 | H15: =$O$2*EXP(G15) -> 9.9541465e+08 | I15: =H15-$O$2 -> -4585351.4 | L15: 13 | M15: -21017306
A16: 14030625 | B16: 8204.5 | C16: 175160 | E16: =LN(B16/B15) -> -0.0082781528 | F16: =LN(C16/C15) -> -0.001568762 | G16: =($P$2*E16)+((1-$P$2)*F16) -> -0.0049234574 | H16: =$O$2*EXP(G16) -> 9.9508864e+08 | I16: =H16-$O$2 -> -4911357 | L16: 14 | M16: -20745237 | N16: VaR 95%
A17: 14030626 | B17: 8201.2 | C17: 175188 | E17: =LN(B17/B16) -> -0.00040229921 | F17: =LN(C17/C16) -> 0.00015984107 | G17: =($P$2*E17)+((1-$P$2)*F17) -> -0.00012122907 | H17: =$O$2*EXP(G17) -> 9.9987878e+08 | I17: =H17-$O$2 -> -121221.72 | L17: 15 | M17: -20152794
A18: 14030627 | B18: 8343.3 | C18: 175919 | E18: =LN(B18/B17) -> 0.017178337 | F18: =LN(C18/C17) -> 0.0041639788 | G18: =($P$2*E18)+((1-$P$2)*F18) -> 0.010671158 | H18: =$O$2*EXP(G18) -> 1.0107283e+09 | I18: =H18-$O$2 -> 10728298 | L18: 16 | M18: -19702217
A19: 14030628 | B19: 8477.2 | C19: 177148 | E19: =LN(B19/B18) -> 0.015921385 | F19: =LN(C19/C18) -> 0.0069618796 | G19: =($P$2*E19)+((1-$P$2)*F19) -> 0.011441632 | H19: =$O$2*EXP(G19) -> 1.0115073e+09 | I19: =H19-$O$2 -> 11507338 | L19: 17 | M19: -19657277
A20: 14030701 | B20: 8565.1 | C20: 177430 | E20: =LN(B20/B19) -> 0.010315601 | F20: =LN(C20/C19) -> 0.0015906236 | G20: =($P$2*E20)+((1-$P$2)*F20) -> 0.005953112 | H20: =$O$2*EXP(G20) -> 1.0059709e+09 | I20: =H20-$O$2 -> 5970867 | L20: 18 | M20: -19002642
A21: 14030702 | B21: 8749.2 | C21: 178511 | E21: =LN(B21/B20) -> 0.02126646 | F21: =LN(C21/C20) -> 0.006074059 | G21: =($P$2*E21)+((1-$P$2)*F21) -> 0.01367026 | H21: =$O$2*EXP(G21) -> 1.0137641e+09 | I21: =H21-$O$2 -> 13764125 | L21: 19 | M21: -18992261
A22: 14030703 | B22: 8973.4 | C22: 180565 | E22: =LN(B22/B21) -> 0.025302378 | F22: =LN(C22/C21) -> 0.0114406 | G22: =($P$2*E22)+((1-$P$2)*F22) -> 0.018371489 | H22: =$O$2*EXP(G22) -> 1.0185413e+09 | I22: =H22-$O$2 -> 18541283 | L22: 20 | M22: -18279810
A23: 14030704 | B23: 9157.7 | C23: 180482 | E23: =LN(B23/B22) -> 0.02033041 | F23: =LN(C23/C22) -> -0.00045977394 | G23: =($P$2*E23)+((1-$P$2)*F23) -> 0.009935318 | H23: =$O$2*EXP(G23) -> 1.0099848e+09 | I23: =H23-$O$2 -> 9984837.1 | L23: 21 | M23: -18257826
A24: 14030707 | B24: 9116.6 | C24: 179807 | E24: =LN(B24/B23) -> -0.0044981279 | F24: =LN(C24/C23) -> -0.0037469964 | G24: =($P$2*E24)+((1-$P$2)*F24) -> -0.0041225621 | H24: =$O$2*EXP(G24) -> 9.9588592e+08 | I24: =H24-$O$2 -> -4114076 | L24: 22 | M24: -18081352
A25: 14030708 | B25: 9073.5 | C25: 179252 | E25: =LN(B25/B24) -> -0.0047388503 | F25: =LN(C25/C24) -> -0.0030914164 | G25: =($P$2*E25)+((1-$P$2)*F25) -> -0.0039151334 | H25: =$O$2*EXP(G25) -> 9.9609252e+08 | I25: =H25-$O$2 -> -3907479.2 | L25: 23 | M25: -16793919
A26: 14030709 | B26: 9036.5 | C26: 178763 | E26: =LN(B26/B25) -> -0.0040861459 | F26: =LN(C26/C25) -> -0.0027317308 | G26: =($P$2*E26)+((1-$P$2)*F26) -> -0.0034089384 | H26: =$O$2*EXP(G26) -> 9.9659687e+08 | I26: =H26-$O$2 -> -3403134.5 | L26: 24 | M26: -16051788
A27: 14030710 | B27: 8997.3 | C27: 178034 | E27: =LN(B27/B26) -> -0.004347399 | F27: =LN(C27/C26) -> -0.0040863629 | G27: =($P$2*E27)+((1-$P$2)*F27) -> -0.0042168809 | H27: =$O$2*EXP(G27) -> 9.95792e+08 | I27: =H27-$O$2 -> -4208002.4 | L27: 25 | M27: -15918814
A28: 14030711 | B28: 8940.1 | C28: 177223 | E28: =LN(B28/B27) -> -0.0063777575 | F28: =LN(C28/C27) -> -0.0045657167 | G28: =($P$2*E28)+((1-$P$2)*F28) -> -0.0054717371 | H28: =$O$2*EXP(G28) -> 9.9454321e+08 | I28: =H28-$O$2 -> -5456794.4 | L28: 26 | M28: -15214214
... A252: 14040631 | B252: 14857.7 | C252: 236267 | E252: =LN(B252/B251) -> 0.022853508 | F252: =LN(C252/C251) -> 0.012577336 | G252: =($P$2*E252)+((1-$P$2)*F252) -> 0.017715422 | H252: =$O$2*EXP(G252) -> 1.0178733e+09 | I252: =H252-$O$2 -> 17873271 | L252: 250 | M252: 32133767

Sheet Backtesting01
A1: تاریخ | B1: شاخص قیمت | C1: بازدهی | D1: مجذور بازدهی | E1: ارزش دارایی | F1: سود یا زیان | G1: VaR Simple | H1: VaR-SMA25 | I1: VaR-SMA50 | J1: VaR-SMA100 | K1: روش ساده | L1: میانگین متحرک 25 | M1: میانگین متحرک 50 | N1: میانگین متحرک 100
A2: 14030531 | B2: 7856.4 | C2: 0.0035575655 | D2: 1.2656272e-05 | E2: 96077590 | G2: -5865170.8 | H2: -2330413.6 | I2: -2641957.2 | J2: -2733376.4
A3: 14030603 | B3: 7940 | C3: 0.010584789 | D3: 0.00011203776 | E3: 97094551 | F3: =E3-E2 -> 1016961 | G3: -5927252.4 | H3: -2358395.7 | I3: -2669321.7 | J3: -2763009.6 | K3: =IF(F3<G3,1,0) -> 0 | L3: =IF(F3<H3,1,0) -> 0 | M3: =IF(F3<I3,1,0) -> 0 | N3: =IF(F3<J3,1,0) -> 0
A4: 14030605 | B4: 7967.6 | C4: 0.003470043 | D4: 1.2041198e-05 | E4: 97431474 | F4: =E4-E3 -> 336922.26 | G4: -5947820.3 | H4: -2416716.1 | I4: -2692134 | J4: -2783081.8 | K4: =IF(F4<G4,1,0) -> 0 | L4: =IF(F4<H4,1,0) -> 0 | M4: =IF(F4<I4,1,0) -> 0 | N4: =IF(F4<J4,1,0) -> 0
A5: 14030606 | B5: 8000.3 | C5: 0.0040957228 | D5: 1.6774945e-05 | E5: 97830526 | F5: =E5-E4 -> 399052.3 | G5: -5972180.9 | H5: -2426394.8 | I5: -2702460.5 | J5: -2793499 | K5: =IF(F5<G5,1,0) -> 0 | L5: =IF(F5<H5,1,0) -> 0 | M5: =IF(F5<I5,1,0) -> 0 | N5: =IF(F5<J5,1,0) -> 0
A6: 14030607 | B6: 8053.2 | C6: 0.006590487 | D6: 4.3434519e-05 | E6: 98475277 | F6: =E6-E5 -> 644750.81 | G6: -6011540.5 | H6: -2340147.1 | I6: -2583307.5 | J6: -2780628.9 | K6: =IF(F6<G6,1,0) -> 0 | L6: =IF(F6<H6,1,0) -> 0 | M6: =IF(F6<I6,1,0) -> 0 | N6: =IF(F6<J6,1,0) -> 0
A7: 14030610 | B7: 8149.7 | C7: 0.011911589 | D7: 0.00014188595 | E7: 99648274 | F7: =E7-E6 -> 1172997 | G7: -6083147.5 | H7: -2387091.4 | I7: -2610044.6 | J7: -2806075.2 | K7: =IF(F7<G7,1,0) -> 0 | L7: =IF(F7<H7,1,0) -> 0 | M7: =IF(F7<I7,1,0) -> 0 | N7: =IF(F7<J7,1,0) -> 0
A8: 14030611 | B8: 8242.6 | C8: 0.011334711 | D8: 0.00012847568 | E8: 1.0077776e+08 | F8: =E8-E7 -> 1129484.4 | G8: -6152098.2 | H8: -2477798.6 | I8: -2657985.9 | J8: -2848971.3 | K8: =IF(F8<G8,1,0) -> 0 | L8: =IF(F8<H8,1,0) -> 0 | M8: =IF(F8<I8,1,0) -> 0 | N8: =IF(F8<J8,1,0) -> 0
A9: 14030613 | B9: 8262.6 | C9: 0.0024234798 | D9: 5.8732546e-06 | E9: 1.0102199e+08 | F9: =E9-E8 -> 244232.87 | G9: -6167007.7 | H9: -2542591.1 | I9: -2691416.6 | J9: -2867783.1 | K9: =IF(F9<G9,1,0) -> 0 | L9: =IF(F9<H9,1,0) -> 0 | M9: =IF(F9<I9,1,0) -> 0 | N9: =IF(F9<J9,1,0) -> 0
A10: 14030617 | B10: 8217.8 | C10: -0.0054367746 | D10: 2.9558518e-05 | E10: 1.0047276e+08 | F10: =E10-E9 -> -549233.8 | G10: -6133479 | H10: -2523058.2 | I10: -2677745.9 | J10: -2850440.8 | K10: =IF(F10<G10,1,0) -> 0 | L10: =IF(F10<H10,1,0) -> 0 | M10: =IF(F10<I10,1,0) -> 0 | N10: =IF(F10<J10,1,0) -> 0
A11: 14030618 | B11: 8181.7 | C11: -0.0044025804 | D11: 1.9382714e-05 | E11: 1.0003042e+08 | F11: =E11-E10 -> -442339.39 | G11: -6106475.9 | H11: -2443161.5 | I11: -2672004.5 | J11: -2840166.9 | K11: =IF(F11<G11,1,0) -> 0 | L11: =IF(F11<H11,1,0) -> 0 | M11: =IF(F11<I11,1,0) -> 0 | N11: =IF(F11<J11,1,0) -> 0
A12: 14030619 | B12: 8258.8 | C12: 0.0093793455 | D12: 8.7972123e-05 | E12: 1.0096864e+08 | F12: =E12-E11 -> 938219.85 | G12: -6163750.7 | H12: -2467796.8 | I12: -2700596.4 | J12: -2852764.1 | K12: =IF(F12<G12,1,0) -> 0 | L12: =IF(F12<H12,1,0) -> 0 | M12: =IF(F12<I12,1,0) -> 0 | N12: =IF(F12<J12,1,0) -> 0
A13: 14030620 | B13: 8285.1 | C13: 0.0031794223 | D13: 1.0108726e-05 | E13: 1.0128966e+08 | F13: =E13-E12 -> 321021.94 | G13: -6183347.8 | H13: -2029807 | I13: -2726927.6 | J13: -2870483.2 | K13: =IF(F13<G13,1,0) -> 0 | L13: =IF(F13<H13,1,0) -> 0 | M13: =IF(F13<I13,1,0) -> 0 | N13: =IF(F13<J13,1,0) -> 0
A14: 14030621 | B14: 8309.4 | C14: 0.0029286833 | D14: 8.5771858e-06 | E14: 1.0158631e+08 | F14: =E14-E13 -> 296645.33 | G14: -6201456.9 | H14: -1512067.7 | I14: -2734111.4 | J14: -2833557.6 | K14: =IF(F14<G14,1,0) -> 0 | L14: =IF(F14<H14,1,0) -> 0 | M14: =IF(F14<I14,1,0) -> 0 | N14: =IF(F14<J14,1,0) -> 0
... A252: 14040631 | B252: 14857.7 | C252: 0.022853508 | D252: 0.00052228285 | E252: 1.7554268e+08 | F252: =E252-E251 -> 3922131.7 | G252: -10716212 | H252: -6312122.7 | I252: -6425465.6 | J252: -7382080.1 | K252: =IF(F252<G252,1,0) -> 0 | L252: =IF(F252<H252,1,0) -> 0 | M252: =IF(F252<I252,1,0) -> 0 | N252: =IF(F252<J252,1,0) -> 0
K253: =SUM(K3:K252) -> 1 | L253: =SUM(L3:L252) -> 2 | M253: =SUM(M3:M252) -> 2 | N253: =SUM(N3:N252) -> 2

Sheet Backtesting02
A1: N | B1: 250 | C1: 0.01
A2: X | B2: p | C2: Sum p | D2: 1-C
A3: 0 | B3: =_xlfn.BINOM.DIST(A3,$B$1,$C$1,FALSE) -> 0.081058516 | C3: =_xlfn.BINOM.DIST(A3,$B$1,$C$1,TRUE) -> 0.081058516 | D3: =1-C3 -> 0.91894148
A4: 1 | B4: =_xlfn.BINOM.DIST(A4,$B$1,$C$1,FALSE) -> 0.20469322 | C4: =_xlfn.BINOM.DIST(A4,$B$1,$C$1,TRUE) -> 0.28575174 | D4: =1-C4 -> 0.71424826
A5: 2 | B5: =_xlfn.BINOM.DIST(A5,$B$1,$C$1,FALSE) -> 0.25741723 | C5: =_xlfn.BINOM.DIST(A5,$B$1,$C$1,TRUE) -> 0.54316897 | D5: =1-C5 -> 0.45683103
A6: 3 | B6: =_xlfn.BINOM.DIST(A6,$B$1,$C$1,FALSE) -> 0.21494772 | C6: =_xlfn.BINOM.DIST(A6,$B$1,$C$1,TRUE) -> 0.7581167 | D6: =1-C6 -> 0.2418833
A7: 4 | B7: =_xlfn.BINOM.DIST(A7,$B$1,$C$1,FALSE) -> 0.13407093 | C7: =_xlfn.BINOM.DIST(A7,$B$1,$C$1,TRUE) -> 0.89218763 | D7: =1-C7 -> 0.10781237
A8: 5 | B8: =_xlfn.BINOM.DIST(A8,$B$1,$C$1,FALSE) -> 0.066629189 | C8: =_xlfn.BINOM.DIST(A8,$B$1,$C$1,TRUE) -> 0.95881682 | D8: =1-C8 -> 0.041183184
A9: 6 | B9: =_xlfn.BINOM.DIST(A9,$B$1,$C$1,FALSE) -> 0.027481736 | C9: =_xlfn.BINOM.DIST(A9,$B$1,$C$1,TRUE) -> 0.98629855 | D9: =1-C9 -> 0.013701448
A10: 7 | B10: =_xlfn.BINOM.DIST(A10,$B$1,$C$1,FALSE) -> 0.0096761091 | C10: =_xlfn.BINOM.DIST(A10,$B$1,$C$1,TRUE) -> 0.99597466 | D10: =1-C10 -> 0.0040253387
A11: 8 | B11: =_xlfn.BINOM.DIST(A11,$B$1,$C$1,FALSE) -> 0.0029688062 | C11: =_xlfn.BINOM.DIST(A11,$B$1,$C$1,TRUE) -> 0.99894347 | D11: =1-C11 -> 0.0010565325
A12: 9 | B12: =_xlfn.BINOM.DIST(A12,$B$1,$C$1,FALSE) -> 0.00080634243 | C12: =_xlfn.BINOM.DIST(A12,$B$1,$C$1,TRUE) -> 0.99974981 | D12: =1-C12 -> 0.00025019007
A13: 10 | B13: =_xlfn.BINOM.DIST(A13,$B$1,$C$1,FALSE) -> 0.00019629144 | C13: =_xlfn.BINOM.DIST(A13,$B$1,$C$1,TRUE) -> 0.9999461 | D13: =1-C13 -> 5.3898629e-05

Sheet Backtesting03
A1: ـ | B1: α | C1: π | D1: x | E1: N | F1: LR | G1: سطح خطا | H1: آماره | I1: نتیجه آزمون
A2: روش ساده | B2: 0.01 | C2: =D2/E2 -> 0.004 | D2: =Backtesting01!K253 -> 1 | E2: =COUNT(Backtesting01!K3:K252) -> 250 | F2: =-2*LN(((B2^D2)*((1-B2)^(E2-D2)))/((C2^D2)*((1-C2)^(E2-D2)))) -> 1.1764911 | G2: 0.1 | H2: =CHIINV(G2,1) -> 2.7055435 | I2: =IF(F2>H2,"رد","قبول") -> قبول
A3: میانگین متحرک 25 | B3: 0.01 | C3: =D3/E3 -> 0.008 | D3: =Backtesting01!L253 -> 2 | E3: =COUNT(Backtesting01!L3:L252) -> 250 | F3: =-2*LN(((B3^D3)*((1-B3)^(E3-D3)))/((C3^D3)*((1-C3)^(E3-D3)))) -> 0.10843522 | G3: 0.1 | H3: =CHIINV(G3,1) -> 2.7055435 | I3: =IF(F3>H3,"رد","قبول") -> قبول
A4: میانگین متحرک 50 | B4: 0.01 | C4: =D4/E4 -> 0.008 | D4: =Backtesting01!M253 -> 2 | E4: =COUNT(Backtesting01!M3:M252) -> 250 | F4: =-2*LN(((B4^D4)*((1-B4)^(E4-D4)))/((C4^D4)*((1-C4)^(E4-D4)))) -> 0.10843522 | G4: 0.1 | H4: =CHIINV(G4,1) -> 2.7055435 | I4: =IF(F4>H4,"رد","قبول") -> قبول
A5: میانگین متحرک 100 | B5: 0.01 | C5: =D5/E5 -> 0.008 | D5: =Backtesting01!N253 -> 2 | E5: =COUNT(Backtesting01!N3:N252) -> 250 | F5: =-2*LN(((B5^D5)*((1-B5)^(E5-D5)))/((C5^D5)*((1-C5)^(E5-D5)))) -> 0.10843522 | G5: 0.1 | H5: =CHIINV(G5,1) -> 2.7055435 | I5: =IF(F5>H5,"رد","قبول") -> قبول

Sheet MonteCarlo01
A1: تاریخ | B1: قیمت پایانی اهرم | C1: بازدهی | E1: تاریخ | F1: قیمت پایانی وبملت | G1: بازدهی
A2: 14030807 | B2: 15690 | E2: 14030807 | F2: 574.5 | I2: اختیار خرید بر روی اهرم (موقعیت خرید) | U2: اختیار خرید بر روی وبملت (موقعیت فروش)
A3: 14030808 | B3: 15470 | C3: -0.014120902 | E3: 14030808 | F3: 577.95 | G3: 0.0059872625
A4: 14030809 | B4: 15650 | C4: 0.011568252 | E4: 14030809 | F4: 588.59 | G4: 0.018242486
A5: 14030812 | B5: 15850 | C5: 0.012698583 | E5: 14030812 | F5: 589.74 | G5: 0.0019519156 | I5: پارامترها | L5: مقادیر فعلی | U5: پارامترها | X5: مقادیر فعلی
A6: 14030813 | B6: 15380 | C6: -0.030101536 | E6: 14030813 | F6: 572.2 | G6: -0.030193181 | I6: قیمت توافقی | J6: 30000 | L6: S | M6: d1 | N6: d2 | O6: Φ(d1) | P6: Φ(d2) | Q6: c | U6: قیمت توافقی | V6: 1300 | X6: S | Y6: d1 | Z6: d2 | AA6: Φ(d1) | AB6: Φ(d2) | AC6: c
